Workbook
Name ddgdghbfgdxf: #REF!
Name _EEE32: #REF!
Name B.2.14: #REF!
Name _MMM48: #REF!
Name _______new8: #REF!
Name _CTK5: #REF!
Name sts: #REF!
Name _2__123Graph_XCHART_1A: #REF!
Name Range3: #REF!
Name _LLL05: #REF!
Name GHI: #REF!
Name lumas: #REF!
Name b15.45: #REF!
Name _1: #REF!
Name _MMM07: #REF!
Name FORM917: #REF!
Name KOEF: #REF!
Name vvv: #REF!
Name Contractor: #REF!
Name URAIAN542: #REF!
Name Analisa101D: #REF!
Name asdAS: #REF!
Name wewe: #REF!
Name display_area_2: #REF!
Name __123Graph_ACHART1: #REF!
Name ne: #REF!
Name _EEE24: #REF!
Name cxvcxzcvz: #REF!
Name _Parse_In: #REF!
Name BGG: #REF!
Name _EEE09: #REF!
Name _EEE14: #REF!
Name __new8: #REF!
Name dldl160: #REF!
Name dw: #REF!
Name _MMM36: #REF!
Name _EEE08: #REF!
Name FORM331: #REF!
Name __123Graph_A: #REF!
Name FORM322: #REF!
Name _2: #REF!
Name SDD: #REF!
Name _MMM35: #REF!
Name DELG2: #REF!
Name _EEE12: #REF!
Name bronjong4: #REF!
Name valuation: #REF!
Name _MMM42: #REF!
Name jndfhnszlfbs: #REF!
Name tbl_ProdInfo: #REF!
Name hgfhgrtdghtrdhg: #REF!
Name MATERIAL: #REF!
Name EDF: #REF!
Name _EEE33: #REF!
Name SpecialPrice: #REF!
Name URAIAN522: #REF!
Name _EEE04: #REF!
Name _EEE15: #REF!
Name b15.40: #REF!
Name FORM542: #REF!

Sheet Summary
L2: Data date as of | N2: 46150
A4: P25045 - ACRES BW Progress Status (Element pc wise)
A5: Zone | B5: Villa | C5: Reqd.Qty | D5: Issued Qty | E5: Cast Qty | F5: Remain to Cast Qty | G5: %Cast | H5: Deliver Qty | I5: Remain to Deliver Qty | J5: %Del | K5: Factory stock | L5: Install Qty | M5: Remain to Install | N5: %Install | O5: Remarks | P5: Balance to issue
A6: J1B | B6: J123 | C6: 22 | D6: =SUMIFS('Element wise-detail Summary'!$F$3:$F$1048576,'Element wise-detail Summary'!$B$3:$B$1048576,Summary!$A6,'Element wise-detail Summary'!$C$3:$C$1048576,Summary!B6) -> 22 | E6: =SUMIFS('Element wise-detail Summary'!$G$3:$G$1048576,'Element wise-detail Summary'!$B$3:$B$1048576,Summary!$A6,'Element wise-detail Summary'!$C$3:$C$1048576,Summary!B6) -> 22 | F6: =D6-E6 -> 0 | G6: =E6/C6 -> 100% | H6: =SUMIFS('Element wise-detail Summary'!$I$3:$I$1048576,'Element wise-detail Summary'!$B$3:$B$1048576,A6,'Element wise-detail Summary'!$C$3:$C$1048576,B6) -> 22 | I6: =D6-H6 -> 0 | J6: =H6/C6 -> 100% | K6: =E6-H6 -> 0 | L6: =SUMIFS('Element wise-detail Summary'!$M$3:$M$1048576,'Element wise-detail Summary'!$B$3:$B$1048576,A6,'Element wise-detail Summary'!$C$3:$C$1048576,B6) -> 22 | M6: =D6-L6 -> 0 | N6: =L6/C6 -> 100% | O6: MOCKUP -65 NOS | P6: =+C6-D6 -> 0
A7: J1B | B7: J124 | C7: 22 | D7: =SUMIFS('Element wise-detail Summary'!$F$3:$F$1048576,'Element wise-detail Summary'!$B$3:$B$1048576,Summary!$A7,'Element wise-detail Summary'!$C$3:$C$1048576,Summary!B7) -> 22 | E7: =SUMIFS('Element wise-detail Summary'!$G$3:$G$1048576,'Element wise-detail Summary'!$B$3:$B$1048576,Summary!$A7,'Element wise-detail Summary'!$C$3:$C$1048576,Summary!B7) -> 22 | F7: =D7-E7 -> 0 | G7: =E7/C7 -> 100% | H7: =SUMIFS('Element wise-detail Summary'!$I$3:$I$1048576,'Element wise-detail Summary'!$B$3:$B$1048576,A7,'Element wise-detail Summary'!$C$3:$C$1048576,B7) -> 22 | I7: =D7-H7 -> 0 | J7: =H7/C7 -> 100% | K7: =E7-H7 -> 0 | L7: =SUMIFS('Element wise-detail Summary'!$M$3:$M$1048576,'Element wise-detail Summary'!$B$3:$B$1048576,A7,'Element wise-detail Summary'!$C$3:$C$1048576,B7) -> 22 | M7: =D7-L7 -> 0 | N7: =L7/C7 -> 100% | P7: =+C7-D7 -> 0
A8: J1B | B8: J125 | C8: 21 | D8: =SUMIFS('Element wise-detail Summary'!$F$3:$F$1048576,'Element wise-detail Summary'!$B$3:$B$1048576,Summary!$A8,'Element wise-detail Summary'!$C$3:$C$1048576,Summary!B8) -> 21 | E8: =SUMIFS('Element wise-detail Summary'!$G$3:$G$1048576,'Element wise-detail Summary'!$B$3:$B$1048576,Summary!$A8,'Element wise-detail Summary'!$C$3:$C$1048576,Summary!B8) -> 21 | F8: =D8-E8 -> 0 | G8: =E8/C8 -> 100% | H8: =SUMIFS('Element wise-detail Summary'!$I$3:$I$1048576,'Element wise-detail Summary'!$B$3:$B$1048576,A8,'Element wise-detail Summary'!$C$3:$C$1048576,B8) -> 21 | I8: =D8-H8 -> 0 | J8: =H8/C8 -> 100% | K8: =E8-H8 -> 0 | L8: =SUMIFS('Element wise-detail Summary'!$M$3:$M$1048576,'Element wise-detail Summary'!$B$3:$B$1048576,A8,'Element wise-detail Summary'!$C$3:$C$1048576,B8) -> 21 | M8: =D8-L8 -> 0 | N8: =L8/C8 -> 100% | P8: =+C8-D8 -> 0
A9: J1B | B9: MOCKUP | C9: =SUM(C6:C8) -> 65 | D9: =SUM(D6:D8) -> 65 | E9: =SUM(E6:E8) -> 65 | F9: =SUM(F6:F8) -> 0 | G9: =E9/C9 -> 100% | H9: =SUM(H6:H8) -> 65 | I9: =SUM(I6:I8) -> 0 | J9: =H9/C9 -> 100% | K9: =SUM(K6:K8) -> 0 | L9: =SUM(L6:L8) -> 65 | M9: =SUM(M6:M8) -> 0 | N9: =L9/C9 -> 100% | P9: =+C9-D9 -> 0
P10: =+C10-D10 -> 0
A11: J1B | B11: J126 | C11: 17 | D11: =SUMIFS('Element wise-detail Summary'!$F$3:$F$1048576,'Element wise-detail Summary'!$B$3:$B$1048576,Summary!$A11,'Element wise-detail Summary'!$C$3:$C$1048576,Summary!B11) -> 17 | E11: =SUMIFS('Element wise-detail Summary'!$G$3:$G$1048576,'Element wise-detail Summary'!$B$3:$B$1048576,Summary!$A11,'Element wise-detail Summary'!$C$3:$C$1048576,Summary!B11) -> 17 | F11: =D11-E11 -> 0 | G11: =E11/C11 -> 100% | H11: =SUMIFS('Element wise-detail Summary'!$I$3:$I$1048576,'Element wise-detail Summary'!$B$3:$B$1048576,A11,'Element wise-detail Summary'!$C$3:$C$1048576,B11) -> 11 | I11: =D11-H11 -> 6 | J11: =H11/C11 -> 65% | K11: =E11-H11 -> 6 | L11: =SUMIFS('Element wise-detail Summary'!$M$3:$M$1048576,'Element wise-detail Summary'!$B$3:$B$1048576,A11,'Element wise-detail Summary'!$C$3:$C$1048576,B11) -> 7 | M11: =D11-L11 -> 10 | N11: =L11/C11 -> 41% | P11: =+C11-D11 -> 0 | Q11: =_xlfn.MAXIFS([1]Details!$B:$B,[1]Details!$G:$G,B11) -> #ERROR!
A12: J1B | B12: J127 | C12: 17 | D12: =SUMIFS('Element wise-detail Summary'!$F$3:$F$1048576,'Element wise-detail Summary'!$B$3:$B$1048576,Summary!$A12,'Element wise-detail Summary'!$C$3:$C$1048576,Summary!B12) -> 17 | E12: =SUMIFS('Element wise-detail Summary'!$G$3:$G$1048576,'Element wise-detail Summary'!$B$3:$B$1048576,Summary!$A12,'Element wise-detail Summary'!$C$3:$C$1048576,Summary!B12) -> 17 | F12: =D12-E12 -> 0 | G12: =E12/C12 -> 100% | H12: =SUMIFS('Element wise-detail Summary'!$I$3:$I$1048576,'Element wise-detail Summary'!$B$3:$B$1048576,A12,'Element wise-detail Summary'!$C$3:$C$1048576,B12) -> 9 | I12: =D12-H12 -> 8 | J12: =H12/C12 -> 53% | K12: =E12-H12 -> 8 | L12: =SUMIFS('Element wise-detail Summary'!$M$3:$M$1048576,'Element wise-detail Summary'!$B$3:$B$1048576,A12,'Element wise-detail Summary'!$C$3:$C$1048576,B12) -> 5 | M12: =D12-L12 -> 12 | N12: =L12/C12 -> 29% | P12: =+C12-D12 -> 0 | Q12: =_xlfn.MAXIFS([1]Details!$B:$B,[1]Details!$G:$G,B12) -> #ERROR!
A13: J1B | B13: J128 | C13: 17 | D13: =SUMIFS('Element wise-detail Summary'!$F$3:$F$1048576,'Element wise-detail Summary'!$B$3:$B$1048576,Summary!$A13,'Element wise-detail Summary'!$C$3:$C$1048576,Summary!B13) -> 17 | E13: =SUMIFS('Element wise-detail Summary'!$G$3:$G$1048576,'Element wise-detail Summary'!$B$3:$B$1048576,Summary!$A13,'Element wise-detail Summary'!$C$3:$C$1048576,Summary!B13) -> 17 | F13: =D13-E13 -> 0 | G13: =E13/C13 -> 100% | H13: =SUMIFS('Element wise-detail Summary'!$I$3:$I$1048576,'Element wise-detail Summary'!$B$3:$B$1048576,A13,'Element wise-detail Summary'!$C$3:$C$1048576,B13) -> 11 | I13: =D13-H13 -> 6 | J13: =H13/C13 -> 65% | K13: =E13-H13 -> 6 | L13: =SUMIFS('Element wise-detail Summary'!$M$3:$M$1048576,'Element wise-detail Summary'!$B$3:$B$1048576,A13,'Element wise-detail Summary'!$C$3:$C$1048576,B13) -> 5 | M13: =D13-L13 -> 12 | N13: =L13/C13 -> 29% | O13: 4 nos EXT | P13: =+C13-D13 -> 0 | Q13: =_xlfn.MAXIFS([1]Details!$B:$B,[1]Details!$G:$G,B13) -> #ERROR!
A14: J1B | B14: J129 | C14: 17 | D14: =SUMIFS('Element wise-detail Summary'!$F$3:$F$1048576,'Element wise-detail Summary'!$B$3:$B$1048576,Summary!$A14,'Element wise-detail Summary'!$C$3:$C$1048576,Summary!B14) -> 17 | E14: =SUMIFS('Element wise-detail Summary'!$G$3:$G$1048576,'Element wise-detail Summary'!$B$3:$B$1048576,Summary!$A14,'Element wise-detail Summary'!$C$3:$C$1048576,Summary!B14) -> 13 | F14: =D14-E14 -> 4 | G14: =E14/C14 -> 76% | H14: =SUMIFS('Element wise-detail Summary'!$I$3:$I$1048576,'Element wise-detail Summary'!$B$3:$B$1048576,A14,'Element wise-detail Summary'!$C$3:$C$1048576,B14) -> 10 | I14: =D14-H14 -> 7 | J14: =H14/C14 -> 59% | K14: =E14-H14 -> 3 | L14: =SUMIFS('Element wise-detail Summary'!$M$3:$M$1048576,'Element wise-detail Summary'!$B$3:$B$1048576,A14,'Element wise-detail Summary'!$C$3:$C$1048576,B14) -> 5 | M14: =D14-L14 -> 12 | N14: =L14/C14 -> 29% | O14: 4 nos EXT | P14: =+C14-D14 -> 0 | Q14: =_xlfn.MAXIFS([1]Details!$B:$B,[1]Details!$G:$G,B14) -> #ERROR!
A15: J1B | B15: J130 | C15: 17 | D15: =SUMIFS('Element wise-detail Summary'!$F$3:$F$1048576,'Element wise-detail Summary'!$B$3:$B$1048576,Summary!$A15,'Element wise-detail Summary'!$C$3:$C$1048576,Summary!B15) -> 17 | E15: =SUMIFS('Element wise-detail Summary'!$G$3:$G$1048576,'Element wise-detail Summary'!$B$3:$B$1048576,Summary!$A15,'Element wise-detail Summary'!$C$3:$C$1048576,Summary!B15) -> 13 | F15: =D15-E15 -> 4 | G15: =E15/C15 -> 76% | H15: =SUMIFS('Element wise-detail Summary'!$I$3:$I$1048576,'Element wise-detail Summary'!$B$3:$B$1048576,A15,'Element wise-detail Summary'!$C$3:$C$1048576,B15) -> 11 | I15: =D15-H15 -> 6 | J15: =H15/C15 -> 65% | K15: =E15-H15 -> 2 | L15: =SUMIFS('Element wise-detail Summary'!$M$3:$M$1048576,'Element wise-detail Summary'!$B$3:$B$1048576,A15,'Element wise-detail Summary'!$C$3:$C$1048576,B15) -> 10 | M15: =D15-L15 -> 7 | N15: =L15/C15 -> 59% | O15: 4 nos EXT | P15: =+C15-D15 -> 0 | Q15: =_xlfn.MAXIFS([1]Details!$B:$B,[1]Details!$G:$G,B15) -> #ERROR!
A16: J1B | B16: J131 | C16: 17 | D16: =SUMIFS('Element wise-detail Summary'!$F$3:$F$1048576,'Element wise-detail Summary'!$B$3:$B$1048576,Summary!$A16,'Element wise-detail Summary'!$C$3:$C$1048576,Summary!B16) -> 17 | E16: =SUMIFS('Element wise-detail Summary'!$G$3:$G$1048576,'Element wise-detail Summary'!$B$3:$B$1048576,Summary!$A16,'Element wise-detail Summary'!$C$3:$C$1048576,Summary!B16) -> 13 | F16: =D16-E16 -> 4 | G16: =E16/C16 -> 76% | H16: =SUMIFS('Element wise-detail Summary'!$I$3:$I$1048576,'Element wise-detail Summary'!$B$3:$B$1048576,A16,'Element wise-detail Summary'!$C$3:$C$1048576,B16) -> 11 | I16: =D16-H16 -> 6 | J16: =H16/C16 -> 65% | K16: =E16-H16 -> 2 | L16: =SUMIFS('Element wise-detail Summary'!$M$3:$M$1048576,'Element wise-detail Summary'!$B$3:$B$1048576,A16,'Element wise-detail Summary'!$C$3:$C$1048576,B16) -> 9 | M16: =D16-L16 -> 8 | N16: =L16/C16 -> 53% | O16: 4 nos EXT | P16: =+C16-D16 -> 0 | Q16: =_xlfn.MAXIFS([1]Details!$B:$B,[1]Details!$G:$G,B16) -> #ERROR!
A17: J1B | B17: J132 | C17: 22 | D17: =SUMIFS('Element wise-detail Summary'!$F$3:$F$1048576,'Element wise-detail Summary'!$B$3:$B$1048576,Summary!$A17,'Element wise-detail Summary'!$C$3:$C$1048576,Summary!B17) -> 22 | E17: =SUMIFS('Element wise-detail Summary'!$G$3:$G$1048576,'Element wise-detail Summary'!$B$3:$B$1048576,Summary!$A17,'Element wise-detail Summary'!$C$3:$C$1048576,Summary!B17) -> 14 | F17: =D17-E17 -> 8 | G17: =E17/C17 -> 64% | H17: =SUMIFS('Element wise-detail Summary'!$I$3:$I$1048576,'Element wise-detail Summary'!$B$3:$B$1048576,A17,'Element wise-detail Summary'!$C$3:$C$1048576,B17) -> 12 | I17: =D17-H17 -> 10 | J17: =H17/C17 -> 55% | K17: =E17-H17 -> 2 | L17: =SUMIFS('Element wise-detail Summary'!$M$3:$M$1048576,'Element wise-detail Summary'!$B$3:$B$1048576,A17,'Element wise-detail Summary'!$C$3:$C$1048576,B17) -> 12 | M17: =D17-L17 -> 10 | N17: =L17/C17 -> 55% | O17: 8 nos EXT | P17: =+C17-D17 -> 0 | Q17: =_xlfn.MAXIFS([1]Details!$B:$B,[1]Details!$G:$G,B17) -> #ERROR!
A18: J1B | B18: J133 | C18: 21 | D18: =SUMIFS('Element wise-detail Summary'!$F$3:$F$1048576,'Element wise-detail Summary'!$B$3:$B$1048576,Summary!$A18,'Element wise-detail Summary'!$C$3:$C$1048576,Summary!B18) -> 21 | E18: =SUMIFS('Element wise-detail Summary'!$G$3:$G$1048576,'Element wise-detail Summary'!$B$3:$B$1048576,Summary!$A18,'Element wise-detail Summary'!$C$3:$C$1048576,Summary!B18) -> 21 | F18: =D18-E18 -> 0 | G18: =E18/C18 -> 100% | H18: =SUMIFS('Element wise-detail Summary'!$I$3:$I$1048576,'Element wise-detail Summary'!$B$3:$B$1048576,A18,'Element wise-detail Summary'!$C$3:$C$1048576,B18) -> 11 | I18: =D18-H18 -> 10 | J18: =H18/C18 -> 52% | K18: =E18-H18 -> 10 | L18: =SUMIFS('Element wise-detail Summary'!$M$3:$M$1048576,'Element wise-detail Summary'!$B$3:$B$1048576,A18,'Element wise-detail Summary'!$C$3:$C$1048576,B18) -> 10 | M18: =D18-L18 -> 11 | N18: =L18/C18 -> 48% | P18: =+C18-D18 -> 0 | Q18: =_xlfn.MAXIFS([1]Details!$B:$B,[1]Details!$G:$G,B18) -> #ERROR!
A19: J1B | B19: =COUNTA(B11:B18) & " NOS" -> 8 NOS | C19: =SUM(C11:C18) -> 145 | D19: =SUM(D11:D18) -> 145 | E19: =SUM(E11:E18) -> 125 | F19: =SUM(F11:F18) -> 20 | G19: =E19/C19 -> 86% | H19: =SUM(H11:H18) -> 86 | I19: =SUM(I11:I18) -> 59 | J19: =H19/C19 -> 59% | K19: =SUM(K11:K18) -> 39 | L19: =SUM(L11:L18) -> 63 | M19: =D19-L19 -> 82 | N19: =L19/C19 -> 43% | P19: =+C19-D19 -> 0
P20: =+C20-D20 -> 0
A21: J1A | B21: J116 | C21: 21 | D21: =SUMIFS('Element wise-detail Summary'!$F$3:$F$1048576,'Element wise-detail Summary'!$B$3:$B$1048576,Summary!$A21,'Element wise-detail Summary'!$C$3:$C$1048576,Summary!B21) -> 21 | E21: =SUMIFS('Element wise-detail Summary'!$G$3:$G$1048576,'Element wise-detail Summary'!$B$3:$B$1048576,Summary!$A21,'Element wise-detail Summary'!$C$3:$C$1048576,Summary!B21) -> 17 | F21: =D21-E21 -> 4 | G21: =E21/C21 -> 81% | H21: =SUMIFS('Element wise-detail Summary'!$I$3:$I$1048576,'Element wise-detail Summary'!$B$3:$B$1048576,A21,'Element wise-detail Summary'!$C$3:$C$1048576,B21) -> 5 | I21: =D21-H21 -> 16 | J21: =H21/C21 -> 24% | K21: =E21-H21 -> 12 | L21: =SUMIFS('Element wise-detail Summary'!$M$3:$M$1048576,'Element wise-detail Summary'!$B$3:$B$1048576,A21,'Element wise-detail Summary'!$C$3:$C$1048576,B21) -> 4 | M21: =D21-L21 -> 17 | N21: =L21/C21 -> 19% | O21: 5 nos EXT | P21: =+C21-D21 -> 0 | Q21: =_xlfn.MAXIFS([1]Details!$B:$B,[1]Details!$G:$G,B21) -> #ERROR!
A22: J1A | B22: J117 | C22: 28 | D22: =SUMIFS('Element wise-detail Summary'!$F$3:$F$1048576,'Element wise-detail Summary'!$B$3:$B$1048576,Summary!$A22,'Element wise-detail Summary'!$C$3:$C$1048576,Summary!B22) -> 28 | E22: =SUMIFS('Element wise-detail Summary'!$G$3:$G$1048576,'Element wise-detail Summary'!$B$3:$B$1048576,Summary!$A22,'Element wise-detail Summary'!$C$3:$C$1048576,Summary!B22) -> 27 | F22: =D22-E22 -> 1 | G22: =E22/C22 -> 96% | H22: =SUMIFS('Element wise-detail Summary'!$I$3:$I$1048576,'Element wise-detail Summary'!$B$3:$B$1048576,A22,'Element wise-detail Summary'!$C$3:$C$1048576,B22) -> 6 | I22: =D22-H22 -> 22 | J22: =H22/C22 -> 21% | K22: =E22-H22 -> 21 | L22: =SUMIFS('Element wise-detail Summary'!$M$3:$M$1048576,'Element wise-detail Summary'!$B$3:$B$1048576,A22,'Element wise-detail Summary'!$C$3:$C$1048576,B22) -> 3 | M22: =D22-L22 -> 25 | N22: =L22/C22 -> 11% | O22: 13 no EXT | P22: =+C22-D22 -> 0 | Q22: =_xlfn.MAXIFS([1]Details!$B:$B,[1]Details!$G:$G,B22) -> #ERROR!
A23: J1A | B23: J118 | C23: 28 | D23: =SUMIFS('Element wise-detail Summary'!$F$3:$F$1048576,'Element wise-detail Summary'!$B$3:$B$1048576,Summary!$A23,'Element wise-detail Summary'!$C$3:$C$1048576,Summary!B23) -> 28 | E23: =SUMIFS('Element wise-detail Summary'!$G$3:$G$1048576,'Element wise-detail Summary'!$B$3:$B$1048576,Summary!$A23,'Element wise-detail Summary'!$C$3:$C$1048576,Summary!B23) -> 28 | F23: =D23-E23 -> 0 | G23: =E23/C23 -> 100% | H23: =SUMIFS('Element wise-detail Summary'!$I$3:$I$1048576,'Element wise-detail Summary'!$B$3:$B$1048576,A23,'Element wise-detail Summary'!$C$3:$C$1048576,B23) -> 8 | I23: =D23-H23 -> 20 | J23: =H23/C23 -> 29% | K23: =E23-H23 -> 20 | L23: =SUMIFS('Element wise-detail Summary'!$M$3:$M$1048576,'Element wise-detail Summary'!$B$3:$B$1048576,A23,'Element wise-detail Summary'!$C$3:$C$1048576,B23) -> 7 | M23: =D23-L23 -> 21 | N23: =L23/C23 -> 25% | O23: 13 no EXT | P23: =+C23-D23 -> 0 | Q23: =_xlfn.MAXIFS([1]Details!$B:$B,[1]Details!$G:$G,B23) -> #ERROR!
A24: J1A | B24: J119 | C24: 25 | D24: =SUMIFS('Element wise-detail Summary'!$F$3:$F$1048576,'Element wise-detail Summary'!$B$3:$B$1048576,Summary!$A24,'Element wise-detail Summary'!$C$3:$C$1048576,Summary!B24) -> 25 | E24: =SUMIFS('Element wise-detail Summary'!$G$3:$G$1048576,'Element wise-detail Summary'!$B$3:$B$1048576,Summary!$A24,'Element wise-detail Summary'!$C$3:$C$1048576,Summary!B24) -> 17 | F24: =D24-E24 -> 8 | G24: =E24/C24 -> 68% | H24: =SUMIFS('Element wise-detail Summary'!$I$3:$I$1048576,'Element wise-detail Summary'!$B$3:$B$1048576,A24,'Element wise-detail Summary'!$C$3:$C$1048576,B24) -> 10 | I24: =D24-H24 -> 15 | J24: =H24/C24 -> 40% | K24: =E24-H24 -> 7 | L24: =SUMIFS('Element wise-detail Summary'!$M$3:$M$1048576,'Element wise-detail Summary'!$B$3:$B$1048576,A24,'Element wise-detail Summary'!$C$3:$C$1048576,B24) -> 6 | M24: =D24-L24 -> 19 | N24: =L24/C24 -> 24% | O24: 8 nos EXT | P24: =+C24-D24 -> 0 | Q24: =_xlfn.MAXIFS([1]Details!$B:$B,[1]Details!$G:$G,B24) -> #ERROR!
A25: J1A | B25: J120 | C25: 21 | D25: =SUMIFS('Element wise-detail Summary'!$F$3:$F$1048576,'Element wise-detail Summary'!$B$3:$B$1048576,Summary!$A25,'Element wise-detail Summary'!$C$3:$C$1048576,Summary!B25) -> 21 | E25: =SUMIFS('Element wise-detail Summary'!$G$3:$G$1048576,'Element wise-detail Summary'!$B$3:$B$1048576,Summary!$A25,'Element wise-detail Summary'!$C$3:$C$1048576,Summary!B25) -> 18 | F25: =D25-E25 -> 3 | G25: =E25/C25 -> 86% | H25: =SUMIFS('Element wise-detail Summary'!$I$3:$I$1048576,'Element wise-detail Summary'!$B$3:$B$1048576,A25,'Element wise-detail Summary'!$C$3:$C$1048576,B25) -> 9 | I25: =D25-H25 -> 12 | J25: =H25/C25 -> 43% | K25: =E25-H25 -> 9 | L25: =SUMIFS('Element wise-detail Summary'!$M$3:$M$1048576,'Element wise-detail Summary'!$B$3:$B$1048576,A25,'Element wise-detail Summary'!$C$3:$C$1048576,B25) -> 6 | M25: =D25-L25 -> 15 | N25: =L25/C25 -> 29% | O25: 5 nos EXT | P25: =+C25-D25 -> 0 | Q25: =_xlfn.MAXIFS([1]Details!$B:$B,[1]Details!$G:$G,B25) -> #ERROR!
A26: J1A | B26: J121 | C26: 20 | D26: =SUMIFS('Element wise-detail Summary'!$F$3:$F$1048576,'Element wise-detail Summary'!$B$3:$B$1048576,Summary!$A26,'Element wise-detail Summary'!$C$3:$C$1048576,Summary!B26) -> 20 | E26: =SUMIFS('Element wise-detail Summary'!$G$3:$G$1048576,'Element wise-detail Summary'!$B$3:$B$1048576,Summary!$A26,'Element wise-detail Summary'!$C$3:$C$1048576,Summary!B26) -> 20 | F26: =D26-E26 -> 0 | G26: =E26/C26 -> 100% | H26: =SUMIFS('Element wise-detail Summary'!$I$3:$I$1048576,'Element wise-detail Summary'!$B$3:$B$1048576,A26,'Element wise-detail Summary'!$C$3:$C$1048576,B26) -> 10 | I26: =D26-H26 -> 10 | J26: =H26/C26 -> 50% | K26: =E26-H26 -> 10 | L26: =SUMIFS('Element wise-detail Summary'!$M$3:$M$1048576,'Element wise-detail Summary'!$B$3:$B$1048576,A26,'Element wise-detail Summary'!$C$3:$C$1048576,B26) -> 10 | M26: =D26-L26 -> 10 | N26: =L26/C26 -> 50% | O26: 4 nos EXT | P26: =+C26-D26 -> 0 | Q26: =_xlfn.MAXIFS([1]Details!$B:$B,[1]Details!$G:$G,B26) -> #ERROR!
A27: J1A | B27: J122 | C27: 20 | D27: =SUMIFS('Element wise-detail Summary'!$F$3:$F$1048576,'Element wise-detail Summary'!$B$3:$B$1048576,Summary!$A27,'Element wise-detail Summary'!$C$3:$C$1048576,Summary!B27) -> 20 | E27: =SUMIFS('Element wise-detail Summary'!$G$3:$G$1048576,'Element wise-detail Summary'!$B$3:$B$1048576,Summary!$A27,'Element wise-detail Summary'!$C$3:$C$1048576,Summary!B27) -> 19 | F27: =D27-E27 -> 1 | G27: =E27/C27 -> 95% | H27: =SUMIFS('Element wise-detail Summary'!$I$3:$I$1048576,'Element wise-detail Summary'!$B$3:$B$1048576,A27,'Element wise-detail Summary'!$C$3:$C$1048576,B27) -> 10 | I27: =D27-H27 -> 10 | J27: =H27/C27 -> 50% | K27: =E27-H27 -> 9 | L27: =SUMIFS('Element wise-detail Summary'!$M$3:$M$1048576,'Element wise-detail Summary'!$B$3:$B$1048576,A27,'Element wise-detail Summary'!$C$3:$C$1048576,B27) -> 10 | M27: =D27-L27 -> 10 | N27: =L27/C27 -> 50% | O27: 4 nos EXT | P27: =+C27-D27 -> 0 | Q27: =_xlfn.MAXIFS([1]Details!$B:$B,[1]Details!$G:$G,B27) -> #ERROR!
A28: J1A | B28: =COUNTA(B21:B27) & " NOS" -> 7 NOS | C28: =SUM(C21:C27) -> 163 | D28: =SUM(D21:D27) -> 163 | E28: =SUM(E21:E27) -> 146 | F28: =SUM(F21:F27) -> 17 | G28: =E28/C28 -> 90% | H28: =SUM(H21:H27) -> 58 | I28: =SUM(I21:I27) -> 105 | J28: =H28/C28 -> 36% | K28: =SUM(K21:K27) -> 88 | L28: =SUM(L21:L27) -> 46 | M28: =D28-L28 -> 117 | N28: =L28/C28 -> 28% | P28: =+C28-D28 -> 0
P29: =+C29-D29 -> 0
A30: J1D | B30: J096 | C30: 21 | D30: =SUMIFS('Element wise-detail Summary'!$F$3:$F$1048576,'Element wise-detail Summary'!$B$3:$B$1048576,Summary!$A30,'Element wise-detail Summary'!$C$3:$C$1048576,Summary!B30) -> 21 | E30: =SUMIFS('Element wise-detail Summary'!$G$3:$G$1048576,'Element wise-detail Summary'!$B$3:$B$1048576,Summary!$A30,'Element wise-detail Summary'!$C$3:$C$1048576,Summary!B30) -> 16 | F30: =D30-E30 -> 5 | G30: =E30/C30 -> 76% | H30: =SUMIFS('Element wise-detail Summary'!$I$3:$I$1048576,'Element wise-detail Summary'!$B$3:$B$1048576,A30,'Element wise-detail Summary'!$C$3:$C$1048576,B30) -> 0 | I30: =D30-H30 -> 21 | J30: =H30/C30 -> 0% | K30: =E30-H30 -> 16 | L30: =SUMIFS('Element wise-detail Summary'!$M$3:$M$1048576,'Element wise-detail Summary'!$B$3:$B$1048576,A30,'Element wise-detail Summary'!$C$3:$C$1048576,B30) -> 0 | M30: =D30-L30 -> 21 | N30: =L30/C30 -> 0% | O30: 5 EXT | P30: =+C30-D30 -> 0 | Q30: =_xlfn.MAXIFS([1]Details!$B:$B,[1]Details!$G:$G,B30) -> #ERROR!
A31: J1D | B31: J097 | C31: 27 | D31: =SUMIFS('Element wise-detail Summary'!$F$3:$F$1048576,'Element wise-detail Summary'!$B$3:$B$1048576,Summary!$A31,'Element wise-detail Summary'!$C$3:$C$1048576,Summary!B31) -> 27 | E31: =SUMIFS('Element wise-detail Summary'!$G$3:$G$1048576,'Element wise-detail Summary'!$B$3:$B$1048576,Summary!$A31,'Element wise-detail Summary'!$C$3:$C$1048576,Summary!B31) -> 22 | F31: =D31-E31 -> 5 | G31: =E31/C31 -> 81% | H31: =SUMIFS('Element wise-detail Summary'!$I$3:$I$1048576,'Element wise-detail Summary'!$B$3:$B$1048576,A31,'Element wise-detail Summary'!$C$3:$C$1048576,B31) -> 0 | I31: =D31-H31 -> 27 | J31: =H31/C31 -> 0% | K31: =E31-H31 -> 22 | L31: =SUMIFS('Element wise-detail Summary'!$M$3:$M$1048576,'Element wise-detail Summary'!$B$3:$B$1048576,A31,'Element wise-detail Summary'!$C$3:$C$1048576,B31) -> 0 | M31: =D31-L31 -> 27 | N31: =L31/C31 -> 0% | O31: 5 EXT | P31: =+C31-D31 -> 0 | Q31: =_xlfn.MAXIFS([1]Details!$B:$B,[1]Details!$G:$G,B31) -> #ERROR!
A32: J1D | B32: J098 | C32: 29 | D32: =SUMIFS('Element wise-detail Summary'!$F$3:$F$1048576,'Element wise-detail Summary'!$B$3:$B$1048576,Summary!$A32,'Element wise-detail Summary'!$C$3:$C$1048576,Summary!B32) -> 29 | E32: =SUMIFS('Element wise-detail Summary'!$G$3:$G$1048576,'Element wise-detail Summary'!$B$3:$B$1048576,Summary!$A32,'Element wise-detail Summary'!$C$3:$C$1048576,Summary!B32) -> 18 | F32: =D32-E32 -> 11 | G32: =E32/C32 -> 62% | H32: =SUMIFS('Element wise-detail Summary'!$I$3:$I$1048576,'Element wise-detail Summary'!$B$3:$B$1048576,A32,'Element wise-detail Summary'!$C$3:$C$1048576,B32) -> 9 | I32: =D32-H32 -> 20 | J32: =H32/C32 -> 31% | K32: =E32-H32 -> 9 | L32: =SUMIFS('Element wise-detail Summary'!$M$3:$M$1048576,'Element wise-detail Summary'!$B$3:$B$1048576,A32,'Element wise-detail Summary'!$C$3:$C$1048576,B32) -> 0 | M32: =D32-L32 -> 29 | N32: =L32/C32 -> 0% | O32: 11 EXT | P32: =+C32-D32 -> 0 | Q32: =_xlfn.MAXIFS([1]Details!$B:$B,[1]Details!$G:$G,B32) -> #ERROR!
A33: J1D | B33: J099 | C33: 25 | D33: =SUMIFS('Element wise-detail Summary'!$F$3:$F$1048576,'Element wise-detail Summary'!$B$3:$B$1048576,Summary!$A33,'Element wise-detail Summary'!$C$3:$C$1048576,Summary!B33) -> 25 | E33: =SUMIFS('Element wise-detail Summary'!$G$3:$G$1048576,'Element wise-detail Summary'!$B$3:$B$1048576,Summary!$A33,'Element wise-detail Summary'!$C$3:$C$1048576,Summary!B33) -> 15 | F33: =D33-E33 -> 10 | G33: =E33/C33 -> 60% | H33: =SUMIFS('Element wise-detail Summary'!$I$3:$I$1048576,'Element wise-detail Summary'!$B$3:$B$1048576,A33,'Element wise-detail Summary'!$C$3:$C$1048576,B33) -> 7 | I33: =D33-H33 -> 18 | J33: =H33/C33 -> 28% | K33: =E33-H33 -> 8 | L33: =SUMIFS('Element wise-detail Summary'!$M$3:$M$1048576,'Element wise-detail Summary'!$B$3:$B$1048576,A33,'Element wise-detail Summary'!$C$3:$C$1048576,B33) -> 7 | M33: =D33-L33 -> 18 | N33: =L33/C33 -> 28% | O33: 9 EXT | P33: =+C33-D33 -> 0 | Q33: =_xlfn.MAXIFS([1]Details!$B:$B,[1]Details!$G:$G,B33) -> #ERROR!
A34: J1D | B34: J100 | C34: 19 | D34: =SUMIFS('Element wise-detail Summary'!$F$3:$F$1048576,'Element wise-detail Summary'!$B$3:$B$1048576,Summary!$A34,'Element wise-detail Summary'!$C$3:$C$1048576,Summary!B34) -> 19 | E34: =SUMIFS('Element wise-detail Summary'!$G$3:$G$1048576,'Element wise-detail Summary'!$B$3:$B$1048576,Summary!$A34,'Element wise-detail Summary'!$C$3:$C$1048576,Summary!B34) -> 15 | F34: =D34-E34 -> 4 | G34: =E34/C34 -> 79% | H34: =SUMIFS('Element wise-detail Summary'!$I$3:$I$1048576,'Element wise-detail Summary'!$B$3:$B$1048576,A34,'Element wise-detail Summary'!$C$3:$C$1048576,B34) -> 1 | I34: =D34-H34 -> 18 | J34: =H34/C34 -> 5% | K34: =E34-H34 -> 14 | L34: =SUMIFS('Element wise-detail Summary'!$M$3:$M$1048576,'Element wise-detail Summary'!$B$3:$B$1048576,A34,'Element wise-detail Summary'!$C$3:$C$1048576,B34) -> 1 | M34: =D34-L34 -> 18 | N34: =L34/C34 -> 5% | O34: 4 EXT | P34: =+C34-D34 -> 0 | Q34: =_xlfn.MAXIFS([1]Details!$B:$B,[1]Details!$G:$G,B34) -> #ERROR!
A35: J1D | B35: =COUNTA(B30:B34) & " NOS" -> 5 NOS | C35: =SUM(C30:C34) -> 121 | D35: =SUM(D30:D34) -> 121 | E35: =SUM(E30:E34) -> 86 | F35: =SUM(F30:F34) -> 35 | G35: =E35/C35 -> 71% | H35: =SUM(H30:H34) -> 17 | I35: =SUM(I30:I34) -> 104 | J35: =H35/C35 -> 14% | K35: =SUM(K30:K34) -> 69 | L35: =SUM(L30:L34) -> 8 | M35: =D35-L35 -> 113 | N35: =L35/C35 -> 7% | P35: =+C35-D35 -> 0
P36: =+C36-D36 -> 0
A37: J1C | B37: J087 | C37: 29 | D37: =SUMIFS('Element wise-detail Summary'!$F$3:$F$1048576,'Element wise-detail Summary'!$B$3:$B$1048576,Summary!$A37,'Element wise-detail Summary'!$C$3:$C$1048576,Summary!B37) -> 29 | E37: =SUMIFS('Element wise-detail Summary'!$G$3:$G$1048576,'Element wise-detail Summary'!$B$3:$B$1048576,Summary!$A37,'Element wise-detail Summary'!$C$3:$C$1048576,Summary!B37) -> 26 | F37: =D37-E37 -> 3 | G37: =E37/C37 -> 90% | H37: =SUMIFS('Element wise-detail Summary'!$I$3:$I$1048576,'Element wise-detail Summary'!$B$3:$B$1048576,A37,'Element wise-detail Summary'!$C$3:$C$1048576,B37) -> 0 | I37: =D37-H37 -> 29 | J37: =H37/C37 -> 0% | K37: =E37-H37 -> 26 | L37: =SUMIFS('Element wise-detail Summary'!$M$3:$M$1048576,'Element wise-detail Summary'!$B$3:$B$1048576,A37,'Element wise-detail Summary'!$C$3:$C$1048576,B37) -> 0 | M37: =D37-L37 -> 29 | N37: =L37/C37 -> 0% | O37: 6 EXT | P37: =+C37-D37 -> 0 | Q37: =_xlfn.MAXIFS([1]Details!$B:$B,[1]Details!$G:$G,B37) -> #ERROR!
A38: J1C | B38: J088 | C38: 16 | D38: =SUMIFS('Element wise-detail Summary'!$F$3:$F$1048576,'Element wise-detail Summary'!$B$3:$B$1048576,Summary!$A38,'Element wise-detail Summary'!$C$3:$C$1048576,Summary!B38) -> 16 | E38: =SUMIFS('Element wise-detail Summary'!$G$3:$G$1048576,'Element wise-detail Summary'!$B$3:$B$1048576,Summary!$A38,'Element wise-detail Summary'!$C$3:$C$1048576,Summary!B38) -> 15 | F38: =D38-E38 -> 1 | G38: =E38/C38 -> 94% | H38: =SUMIFS('Element wise-detail Summary'!$I$3:$I$1048576,'Element wise-detail Summary'!$B$3:$B$1048576,A38,'Element wise-detail Summary'!$C$3:$C$1048576,B38) -> 0 | I38: =D38-H38 -> 16 | J38: =H38/C38 -> 0% | K38: =E38-H38 -> 15 | L38: =SUMIFS('Element wise-detail Summary'!$M$3:$M$1048576,'Element wise-detail Summary'!$B$3:$B$1048576,A38,'Element wise-detail Summary'!$C$3:$C$1048576,B38) -> 0 | M38: =D38-L38 -> 16 | N38: =L38/C38 -> 0% | O38: 4 EXT | P38: =+C38-D38 -> 0 | Q38: =_xlfn.MAXIFS([1]Details!$B:$B,[1]Details!$G:$G,B38) -> #ERROR!
A39: J1C | B39: J089 | C39: 16 | D39: =SUMIFS('Element wise-detail Summary'!$F$3:$F$1048576,'Element wise-detail Summary'!$B$3:$B$1048576,Summary!$A39,'Element wise-detail Summary'!$C$3:$C$1048576,Summary!B39) -> 16 | E39: =SUMIFS('Element wise-detail Summary'!$G$3:$G$1048576,'Element wise-detail Summary'!$B$3:$B$1048576,Summary!$A39,'Element wise-detail Summary'!$C$3:$C$1048576,Summary!B39) -> 15 | F39: =D39-E39 -> 1 | G39: =E39/C39 -> 94% | H39: =SUMIFS('Element wise-detail Summary'!$I$3:$I$1048576,'Element wise-detail Summary'!$B$3:$B$1048576,A39,'Element wise-detail Summary'!$C$3:$C$1048576,B39) -> 0 | I39: =D39-H39 -> 16 | J39: =H39/C39 -> 0% | K39: =E39-H39 -> 15 | L39: =SUMIFS('Element wise-detail Summary'!$M$3:$M$1048576,'Element wise-detail Summary'!$B$3:$B$1048576,A39,'Element wise-detail Summary'!$C$3:$C$1048576,B39) -> 0 | M39: =D39-L39 -> 16 | N39: =L39/C39 -> 0% | O39: 4 EXT | P39: =+C39-D39 -> 0 | Q39: =_xlfn.MAXIFS([1]Details!$B:$B,[1]Details!$G:$G,B39) -> #ERROR!
A40: J1C | B40: J090 | C40: 17 | D40: =SUMIFS('Element wise-detail Summary'!$F$3:$F$1048576,'Element wise-detail Summary'!$B$3:$B$1048576,Summary!$A40,'Element wise-detail Summary'!$C$3:$C$1048576,Summary!B40) -> 17 | E40: =SUMIFS('Element wise-detail Summary'!$G$3:$G$1048576,'Element wise-detail Summary'!$B$3:$B$1048576,Summary!$A40,'Element wise-detail Summary'!$C$3:$C$1048576,Summary!B40) -> 14 | F40: =D40-E40 -> 3 | G40: =E40/C40 -> 82% | H40: =SUMIFS('Element wise-detail Summary'!$I$3:$I$1048576,'Element wise-detail Summary'!$B$3:$B$1048576,A40,'Element wise-detail Summary'!$C$3:$C$1048576,B40) -> 0 | I40: =D40-H40 -> 17 | J40: =H40/C40 -> 0% | K40: =E40-H40 -> 14 | L40: =SUMIFS('Element wise-detail Summary'!$M$3:$M$1048576,'Element wise-detail Summary'!$B$3:$B$1048576,A40,'Element wise-detail Summary'!$C$3:$C$1048576,B40) -> 0 | M40: =D40-L40 -> 17 | N40: =L40/C40 -> 0% | O40: 4 EXT | P40: =+C40-D40 -> 0 | Q40: =_xlfn.MAXIFS([1]Details!$B:$B,[1]Details!$G:$G,B40) -> #ERROR!
A41: J1C | B41: J091 | C41: 17 | D41: =SUMIFS('Element wise-detail Summary'!$F$3:$F$1048576,'Element wise-detail Summary'!$B$3:$B$1048576,Summary!$A41,'Element wise-detail Summary'!$C$3:$C$1048576,Summary!B41) -> 17 | E41: =SUMIFS('Element wise-detail Summary'!$G$3:$G$1048576,'Element wise-detail Summary'!$B$3:$B$1048576,Summary!$A41,'Element wise-detail Summary'!$C$3:$C$1048576,Summary!B41) -> 17 | F41: =D41-E41 -> 0 | G41: =E41/C41 -> 100% | H41: =SUMIFS('Element wise-detail Summary'!$I$3:$I$1048576,'Element wise-detail Summary'!$B$3:$B$1048576,A41,'Element wise-detail Summary'!$C$3:$C$1048576,B41) -> 0 | I41: =D41-H41 -> 17 | J41: =H41/C41 -> 0% | K41: =E41-H41 -> 17 | L41: =SUMIFS('Element wise-detail Summary'!$M$3:$M$1048576,'Element wise-detail Summary'!$B$3:$B$1048576,A41,'Element wise-detail Summary'!$C$3:$C$1048576,B41) -> 0 | M41: =D41-L41 -> 17 | N41: =L41/C41 -> 0% | O41: 3 EXT | P41: =+C41-D41 -> 0 | Q41: =_xlfn.MAXIFS([1]Details!$B:$B,[1]Details!$G:$G,B41) -> #ERROR!
A42: J1C | B42: J092 | C42: 16 | D42: =SUMIFS('Element wise-detail Summary'!$F$3:$F$1048576,'Element wise-detail Summary'!$B$3:$B$1048576,Summary!$A42,'Element wise-detail Summary'!$C$3:$C$1048576,Summary!B42) -> 16 | E42: =SUMIFS('Element wise-detail Summary'!$G$3:$G$1048576,'Element wise-detail Summary'!$B$3:$B$1048576,Summary!$A42,'Element wise-detail Summary'!$C$3:$C$1048576,Summary!B42) -> 13 | F42: =D42-E42 -> 3 | G42: =E42/C42 -> 81% | H42: =SUMIFS('Element wise-detail Summary'!$I$3:$I$1048576,'Element wise-detail Summary'!$B$3:$B$1048576,A42,'Element wise-detail Summary'!$C$3:$C$1048576,B42) -> 0 | I42: =D42-H42 -> 16 | J42: =H42/C42 -> 0% | K42: =E42-H42 -> 13 | L42: =SUMIFS('Element wise-detail Summary'!$M$3:$M$1048576,'Element wise-detail Summary'!$B$3:$B$1048576,A42,'Element wise-detail Summary'!$C$3:$C$1048576,B42) -> 0 | M42: =D42-L42 -> 16 | N42: =L42/C42 -> 0% | O42: 4 EXT | P42: =+C42-D42 -> 0 | Q42: =_xlfn.MAXIFS([1]Details!$B:$B,[1]Details!$G:$G,B42) -> #ERROR!
...

Sheet Element wise-detail Summary
A1: Element ID | B1: Zone | C1: Villa | D1: Location | E1: Product | F1: =SUBTOTAL(9,F3:F1048576) -> 2255 | G1: =SUBTOTAL(9,G3:G1048576) -> 1338 | H1: =SUBTOTAL(9,H3:H1048576) -> 917 | I1: =SUBTOTAL(9,I3:I1048576) -> 226 | J1: =SUBTOTAL(9,J3:J1048576) -> 2029 | K1: =SUBTOTAL(9,K3:K1048576) -> 1112 | M1: =SUBTOTAL(9,M3:M1048576) -> 182 | N1: =SUBTOTAL(9,N3:N1048576) -> 2073 | O1: =SUBTOTAL(9,O3:O1048576) -> 3186.4672 | P1: =SUBTOTAL(9,P3:P1048576) -> 7966.168
F2: Issued Qty | G2: Cast Qty | H2: Remain to Cast | I2: Deliver Qty | J2: Remain to Deliver | K2: Factory stock qty | L2: bay | M2: Install | N2: Remain to Install | O2: Vol.(m3)/pc | P2: Weight (Tons)
A3: 25045-A1A-A001-T1C2-001 | B3: {=XLOOKUP(A3,Data!F:F,Data!G:G)} -> A1A | C3: =MID(A3,11,4) -> A001 | D3: {=XLOOKUP(A3,Data!F:F,Data!C:C)} -> EXT | E3: {=XLOOKUP(A3,Data!F:F,Data!H:H)} -> BW | F3: =SUMIFS(Data!J:J,Data!F:F,A3) -> 1 | G3: =SUMIFS(Cast!C:C,CastElements,A3) -> 0 | H3: =F3-G3 -> 1 | I3: =SUMIFS(Del!C:C,Del!B:B,A3) -> 0 | J3: =F3-I3 -> 1 | K3: =G3-I3 -> 0 | M3: =SUMIFS(Ere!C:C,Ere!B:B,A3) -> 0 | N3: =F3-M3 -> 1 | O3: {=XLOOKUP(A3,Data!F:F,Data!O:O)} -> 1.20 | P3: =+O3*2.5 -> 2.99
A4: 25045-A1A-A001-T1C3-001 | B4: {=XLOOKUP(A4,Data!F:F,Data!G:G)} -> A1A | C4: =MID(A4,11,4) -> A001 | D4: {=XLOOKUP(A4,Data!F:F,Data!C:C)} -> EXT | E4: {=XLOOKUP(A4,Data!F:F,Data!H:H)} -> BW | F4: =SUMIFS(Data!J:J,Data!F:F,A4) -> 1 | G4: =SUMIFS(Cast!C:C,CastElements,A4) -> 0 | H4: =F4-G4 -> 1 | I4: =SUMIFS(Del!C:C,Del!B:B,A4) -> 0 | J4: =F4-I4 -> 1 | K4: =G4-I4 -> 0 | M4: =SUMIFS(Ere!C:C,Ere!B:B,A4) -> 0 | N4: =F4-M4 -> 1 | O4: {=XLOOKUP(A4,Data!F:F,Data!O:O)} -> 1.64 | P4: =+O4*2.5 -> 4.09
A5: 25045-A1A-A001-T1C3-002 | B5: {=XLOOKUP(A5,Data!F:F,Data!G:G)} -> A1A | C5: =MID(A5,11,4) -> A001 | D5: {=XLOOKUP(A5,Data!F:F,Data!C:C)} -> EXT | E5: {=XLOOKUP(A5,Data!F:F,Data!H:H)} -> BW | F5: =SUMIFS(Data!J:J,Data!F:F,A5) -> 1 | G5: =SUMIFS(Cast!C:C,CastElements,A5) -> 0 | H5: =F5-G5 -> 1 | I5: =SUMIFS(Del!C:C,Del!B:B,A5) -> 0 | J5: =F5-I5 -> 1 | K5: =G5-I5 -> 0 | M5: =SUMIFS(Ere!C:C,Ere!B:B,A5) -> 0 | N5: =F5-M5 -> 1 | O5: {=XLOOKUP(A5,Data!F:F,Data!O:O)} -> 1.47 | P5: =+O5*2.5 -> 3.66
A6: 25045-A1A-A001-T2C1-001 | B6: {=XLOOKUP(A6,Data!F:F,Data!G:G)} -> A1A | C6: =MID(A6,11,4) -> A001 | D6: {=XLOOKUP(A6,Data!F:F,Data!C:C)} -> EXT | E6: {=XLOOKUP(A6,Data!F:F,Data!H:H)} -> BW | F6: =SUMIFS(Data!J:J,Data!F:F,A6) -> 1 | G6: =SUMIFS(Cast!C:C,CastElements,A6) -> 1 | H6: =F6-G6 -> 0 | I6: =SUMIFS(Del!C:C,Del!B:B,A6) -> 0 | J6: =F6-I6 -> 1 | K6: =G6-I6 -> 1 | M6: =SUMIFS(Ere!C:C,Ere!B:B,A6) -> 0 | N6: =F6-M6 -> 1 | O6: {=XLOOKUP(A6,Data!F:F,Data!O:O)} -> 1.11 | P6: =+O6*2.5 -> 2.77
A7: 25045-A1A-A001-T2C1-002 | B7: {=XLOOKUP(A7,Data!F:F,Data!G:G)} -> A1A | C7: =MID(A7,11,4) -> A001 | D7: {=XLOOKUP(A7,Data!F:F,Data!C:C)} -> EXT | E7: {=XLOOKUP(A7,Data!F:F,Data!H:H)} -> BW | F7: =SUMIFS(Data!J:J,Data!F:F,A7) -> 1 | G7: =SUMIFS(Cast!C:C,CastElements,A7) -> 0 | H7: =F7-G7 -> 1 | I7: =SUMIFS(Del!C:C,Del!B:B,A7) -> 0 | J7: =F7-I7 -> 1 | K7: =G7-I7 -> 0 | M7: =SUMIFS(Ere!C:C,Ere!B:B,A7) -> 0 | N7: =F7-M7 -> 1 | O7: {=XLOOKUP(A7,Data!F:F,Data!O:O)} -> 1.24 | P7: =+O7*2.5 -> 3.09
A8: 25045-A1A-A001-T2C11-001 | B8: {=XLOOKUP(A8,Data!F:F,Data!G:G)} -> A1A | C8: =MID(A8,11,4) -> A001 | D8: {=XLOOKUP(A8,Data!F:F,Data!C:C)} | E8: {=XLOOKUP(A8,Data!F:F,Data!H:H)} -> BW | F8: =SUMIFS(Data!J:J,Data!F:F,A8) -> 1 | G8: =SUMIFS(Cast!C:C,CastElements,A8) -> 0 | H8: =F8-G8 -> 1 | I8: =SUMIFS(Del!C:C,Del!B:B,A8) -> 0 | J8: =F8-I8 -> 1 | K8: =G8-I8 -> 0 | M8: =SUMIFS(Ere!C:C,Ere!B:B,A8) -> 0 | N8: =F8-M8 -> 1 | O8: {=XLOOKUP(A8,Data!F:F,Data!O:O)} -> 2.77 | P8: =+O8*2.5 -> 6.93
A9: 25045-A1A-A001-T2C12-002 | B9: {=XLOOKUP(A9,Data!F:F,Data!G:G)} -> A1A | C9: =MID(A9,11,4) -> A001 | D9: {=XLOOKUP(A9,Data!F:F,Data!C:C)} | E9: {=XLOOKUP(A9,Data!F:F,Data!H:H)} -> BW | F9: =SUMIFS(Data!J:J,Data!F:F,A9) -> 1 | G9: =SUMIFS(Cast!C:C,CastElements,A9) -> 0 | H9: =F9-G9 -> 1 | I9: =SUMIFS(Del!C:C,Del!B:B,A9) -> 0 | J9: =F9-I9 -> 1 | K9: =G9-I9 -> 0 | M9: =SUMIFS(Ere!C:C,Ere!B:B,A9) -> 0 | N9: =F9-M9 -> 1 | O9: {=XLOOKUP(A9,Data!F:F,Data!O:O)} -> 3.27 | P9: =+O9*2.5 -> 8.17
A10: 25045-A1A-A001-T2C7-001 | B10: {=XLOOKUP(A10,Data!F:F,Data!G:G)} -> A1A | C10: =MID(A10,11,4) -> A001 | D10: {=XLOOKUP(A10,Data!F:F,Data!C:C)} | E10: {=XLOOKUP(A10,Data!F:F,Data!H:H)} -> BW | F10: =SUMIFS(Data!J:J,Data!F:F,A10) -> 1 | G10: =SUMIFS(Cast!C:C,CastElements,A10) -> 1 | H10: =F10-G10 -> 0 | I10: =SUMIFS(Del!C:C,Del!B:B,A10) -> 0 | J10: =F10-I10 -> 1 | K10: =G10-I10 -> 1 | M10: =SUMIFS(Ere!C:C,Ere!B:B,A10) -> 0 | N10: =F10-M10 -> 1 | O10: {=XLOOKUP(A10,Data!F:F,Data!O:O)} -> 2.20 | P10: =+O10*2.5 -> 5.51
A11: 25045-A1A-A001-T2C7-002 | B11: {=XLOOKUP(A11,Data!F:F,Data!G:G)} -> A1A | C11: =MID(A11,11,4) -> A001 | D11: {=XLOOKUP(A11,Data!F:F,Data!C:C)} | E11: {=XLOOKUP(A11,Data!F:F,Data!H:H)} -> BW | F11: =SUMIFS(Data!J:J,Data!F:F,A11) -> 1 | G11: =SUMIFS(Cast!C:C,CastElements,A11) -> 1 | H11: =F11-G11 -> 0 | I11: =SUMIFS(Del!C:C,Del!B:B,A11) -> 0 | J11: =F11-I11 -> 1 | K11: =G11-I11 -> 1 | M11: =SUMIFS(Ere!C:C,Ere!B:B,A11) -> 0 | N11: =F11-M11 -> 1 | O11: {=XLOOKUP(A11,Data!F:F,Data!O:O)} -> 2.21 | P11: =+O11*2.5 -> 5.53
A12: 25045-A1A-A001-T2C8-001 | B12: {=XLOOKUP(A12,Data!F:F,Data!G:G)} -> A1A | C12: =MID(A12,11,4) -> A001 | D12: {=XLOOKUP(A12,Data!F:F,Data!C:C)} | E12: {=XLOOKUP(A12,Data!F:F,Data!H:H)} -> BW | F12: =SUMIFS(Data!J:J,Data!F:F,A12) -> 1 | G12: =SUMIFS(Cast!C:C,CastElements,A12) -> 0 | H12: =F12-G12 -> 1 | I12: =SUMIFS(Del!C:C,Del!B:B,A12) -> 0 | J12: =F12-I12 -> 1 | K12: =G12-I12 -> 0 | M12: =SUMIFS(Ere!C:C,Ere!B:B,A12) -> 0 | N12: =F12-M12 -> 1 | O12: {=XLOOKUP(A12,Data!F:F,Data!O:O)} -> 2.41 | P12: =+O12*2.5 -> 6.03
A13: 25045-A1A-A001-T3C5-001 | B13: {=XLOOKUP(A13,Data!F:F,Data!G:G)} -> A1A | C13: =MID(A13,11,4) -> A001 | D13: {=XLOOKUP(A13,Data!F:F,Data!C:C)} | E13: {=XLOOKUP(A13,Data!F:F,Data!H:H)} -> BW | F13: =SUMIFS(Data!J:J,Data!F:F,A13) -> 1 | G13: =SUMIFS(Cast!C:C,CastElements,A13) -> 1 | H13: =F13-G13 -> 0 | I13: =SUMIFS(Del!C:C,Del!B:B,A13) -> 0 | J13: =F13-I13 -> 1 | K13: =G13-I13 -> 1 | M13: =SUMIFS(Ere!C:C,Ere!B:B,A13) -> 0 | N13: =F13-M13 -> 1 | O13: {=XLOOKUP(A13,Data!F:F,Data!O:O)} -> 2.49 | P13: =+O13*2.5 -> 6.21
A14: 25045-A1A-A001-T3C5-002 | B14: {=XLOOKUP(A14,Data!F:F,Data!G:G)} -> A1A | C14: =MID(A14,11,4) -> A001 | D14: {=XLOOKUP(A14,Data!F:F,Data!C:C)} | E14: {=XLOOKUP(A14,Data!F:F,Data!H:H)} -> BW | F14: =SUMIFS(Data!J:J,Data!F:F,A14) -> 1 | G14: =SUMIFS(Cast!C:C,CastElements,A14) -> 1 | H14: =F14-G14 -> 0 | I14: =SUMIFS(Del!C:C,Del!B:B,A14) -> 0 | J14: =F14-I14 -> 1 | K14: =G14-I14 -> 1 | M14: =SUMIFS(Ere!C:C,Ere!B:B,A14) -> 0 | N14: =F14-M14 -> 1 | O14: {=XLOOKUP(A14,Data!F:F,Data!O:O)} -> 2.33 | P14: =+O14*2.5 -> 5.83
... A2446: 25045-J3B-J041-T1C1-001 | B2446: {=XLOOKUP(A2446,Data!F:F,Data!G:G)} -> J3B | C2446: =MID(A2446,11,4) -> J041 | D2446: {=XLOOKUP(A2446,Data!F:F,Data!C:C)} -> EXT | E2446: {=XLOOKUP(A2446,Data!F:F,Data!H:H)} | F2446: =SUMIFS(Data!J:J,Data!F:F,A2446) -> 1 | G2446: =SUMIFS(Cast!C:C,CastElements,A2446) -> 0 | H2446: =F2446-G2446 -> 1 | I2446: =SUMIFS(Del!C:C,Del!B:B,A2446) -> 0 | J2446: =F2446-I2446 -> 1 | K2446: =G2446-I2446 -> 0 | M2446: =SUMIFS(Ere!C:C,Ere!B:B,A2446) -> 0 | N2446: =F2446-M2446 -> 1 | O2446: {=XLOOKUP(A2446,Data!F:F,Data!O:O)} -> 0.92 | P2446: =+O2446*2.5 -> 2.30
A2447: 25045-J3B-J041-T1C1-002 | B2447: {=XLOOKUP(A2447,Data!F:F,Data!G:G)} -> J3B | C2447: =MID(A2447,11,4) -> J041 | D2447: {=XLOOKUP(A2447,Data!F:F,Data!C:C)} -> EXT | E2447: {=XLOOKUP(A2447,Data!F:F,Data!H:H)} | F2447: =SUMIFS(Data!J:J,Data!F:F,A2447) -> 1 | G2447: =SUMIFS(Cast!C:C,CastElements,A2447) -> 0 | H2447: =F2447-G2447 -> 1 | I2447: =SUMIFS(Del!C:C,Del!B:B,A2447) -> 0 | J2447: =F2447-I2447 -> 1 | K2447: =G2447-I2447 -> 0 | M2447: =SUMIFS(Ere!C:C,Ere!B:B,A2447) -> 0 | N2447: =F2447-M2447 -> 1 | O2447: {=XLOOKUP(A2447,Data!F:F,Data!O:O)} -> 0.92 | P2447: =+O2447*2.5 -> 2.30 | V2447: J041 | W2447: {=GROUPBY($C$3:$C$5445,$F$3:$F$5445,_xleta.SUM,,,,($C$3:$C$5445)=V2447)} -> #NAME?
A2448: 25045-J3B-J041-T1C1-003 | B2448: {=XLOOKUP(A2448,Data!F:F,Data!G:G)} -> J3B | C2448: =MID(A2448,11,4) -> J041 | D2448: {=XLOOKUP(A2448,Data!F:F,Data!C:C)} -> EXT | E2448: {=XLOOKUP(A2448,Data!F:F,Data!H:H)} | F2448: =SUMIFS(Data!J:J,Data!F:F,A2448) -> 1 | G2448: =SUMIFS(Cast!C:C,CastElements,A2448) -> 0 | H2448: =F2448-G2448 -> 1 | I2448: =SUMIFS(Del!C:C,Del!B:B,A2448) -> 0 | J2448: =F2448-I2448 -> 1 | K2448: =G2448-I2448 -> 0 | M2448: =SUMIFS(Ere!C:C,Ere!B:B,A2448) -> 0 | N2448: =F2448-M2448 -> 1 | O2448: {=XLOOKUP(A2448,Data!F:F,Data!O:O)} -> 0.92 | P2448: =+O2448*2.5 -> 2.30 | V2448: J042
A2449: 25045-J3B-J041-T2C1-001 | B2449: {=XLOOKUP(A2449,Data!F:F,Data!G:G)} -> J3B | C2449: =MID(A2449,11,4) -> J041 | D2449: {=XLOOKUP(A2449,Data!F:F,Data!C:C)} | E2449: {=XLOOKUP(A2449,Data!F:F,Data!H:H)} | F2449: =SUMIFS(Data!J:J,Data!F:F,A2449) -> 1 | G2449: =SUMIFS(Cast!C:C,CastElements,A2449) -> 0 | H2449: =F2449-G2449 -> 1 | I2449: =SUMIFS(Del!C:C,Del!B:B,A2449) -> 0 | J2449: =F2449-I2449 -> 1 | K2449: =G2449-I2449 -> 0 | M2449: =SUMIFS(Ere!C:C,Ere!B:B,A2449) -> 0 | N2449: =F2449-M2449 -> 1 | O2449: {=XLOOKUP(A2449,Data!F:F,Data!O:O)} -> 1.22 | P2449: =+O2449*2.5 -> 3.05 | V2449: J043
A2450: 25045-J3B-J041-T2C1-002 | B2450: {=XLOOKUP(A2450,Data!F:F,Data!G:G)} -> J3B | C2450: =MID(A2450,11,4) -> J041 | D2450: {=XLOOKUP(A2450,Data!F:F,Data!C:C)} | E2450: {=XLOOKUP(A2450,Data!F:F,Data!H:H)} | F2450: =SUMIFS(Data!J:J,Data!F:F,A2450) -> 1 | G2450: =SUMIFS(Cast!C:C,CastElements,A2450) -> 0 | H2450: =F2450-G2450 -> 1 | I2450: =SUMIFS(Del!C:C,Del!B:B,A2450) -> 0 | J2450: =F2450-I2450 -> 1 | K2450: =G2450-I2450 -> 0 | M2450: =SUMIFS(Ere!C:C,Ere!B:B,A2450) -> 0 | N2450: =F2450-M2450 -> 1 | O2450: {=XLOOKUP(A2450,Data!F:F,Data!O:O)} -> 1.10 | P2450: =+O2450*2.5 -> 2.75 | V2450: J044
A2451: 25045-J3B-J041-T2C1-003 | B2451: {=XLOOKUP(A2451,Data!F:F,Data!G:G)} -> J3B | C2451: =MID(A2451,11,4) -> J041 | D2451: {=XLOOKUP(A2451,Data!F:F,Data!C:C)} | E2451: {=XLOOKUP(A2451,Data!F:F,Data!H:H)} | F2451: =SUMIFS(Data!J:J,Data!F:F,A2451) -> 1 | G2451: =SUMIFS(Cast!C:C,CastElements,A2451) -> 0 | H2451: =F2451-G2451 -> 1 | I2451: =SUMIFS(Del!C:C,Del!B:B,A2451) -> 0 | J2451: =F2451-I2451 -> 1 | K2451: =G2451-I2451 -> 0 | M2451: =SUMIFS(Ere!C:C,Ere!B:B,A2451) -> 0 | N2451: =F2451-M2451 -> 1 | O2451: {=XLOOKUP(A2451,Data!F:F,Data!O:O)} -> 1.15 | P2451: =+O2451*2.5 -> 2.88 | V2451: J045
A2452: 25045-J3B-J041-T2C1-004 | B2452: {=XLOOKUP(A2452,Data!F:F,Data!G:G)} -> J3B | C2452: =MID(A2452,11,4) -> J041 | D2452: {=XLOOKUP(A2452,Data!F:F,Data!C:C)} -> EXT | E2452: {=XLOOKUP(A2452,Data!F:F,Data!H:H)} | F2452: =SUMIFS(Data!J:J,Data!F:F,A2452) -> 1 | G2452: =SUMIFS(Cast!C:C,CastElements,A2452) -> 0 | H2452: =F2452-G2452 -> 1 | I2452: =SUMIFS(Del!C:C,Del!B:B,A2452) -> 0 | J2452: =F2452-I2452 -> 1 | K2452: =G2452-I2452 -> 0 | M2452: =SUMIFS(Ere!C:C,Ere!B:B,A2452) -> 0 | N2452: =F2452-M2452 -> 1 | O2452: {=XLOOKUP(A2452,Data!F:F,Data!O:O)} -> 0.79 | P2452: =+O2452*2.5 -> 1.98 | V2452: J046
A2453: 25045-J3B-J042-T2C1-001 | B2453: {=XLOOKUP(A2453,Data!F:F,Data!G:G)} -> J3B | C2453: =MID(A2453,11,4) -> J042 | D2453: {=XLOOKUP(A2453,Data!F:F,Data!C:C)} -> EXT | E2453: {=XLOOKUP(A2453,Data!F:F,Data!H:H)} | F2453: =SUMIFS(Data!J:J,Data!F:F,A2453) -> 1 | G2453: =SUMIFS(Cast!C:C,CastElements,A2453) -> 0 | H2453: =F2453-G2453 -> 1 | I2453: =SUMIFS(Del!C:C,Del!B:B,A2453) -> 0 | J2453: =F2453-I2453 -> 1 | K2453: =G2453-I2453 -> 0 | M2453: =SUMIFS(Ere!C:C,Ere!B:B,A2453) -> 0 | N2453: =F2453-M2453 -> 1 | O2453: {=XLOOKUP(A2453,Data!F:F,Data!O:O)} -> 0.79 | P2453: =+O2453*2.5 -> 1.98 | V2453: J047
A2454: 25045-J3B-J043-T2C1-001 | B2454: {=XLOOKUP(A2454,Data!F:F,Data!G:G)} -> J3B | C2454: =MID(A2454,11,4) -> J043 | D2454: {=XLOOKUP(A2454,Data!F:F,Data!C:C)} -> EXT | E2454: {=XLOOKUP(A2454,Data!F:F,Data!H:H)} | F2454: =SUMIFS(Data!J:J,Data!F:F,A2454) -> 1 | G2454: =SUMIFS(Cast!C:C,CastElements,A2454) -> 0 | H2454: =F2454-G2454 -> 1 | I2454: =SUMIFS(Del!C:C,Del!B:B,A2454) -> 0 | J2454: =F2454-I2454 -> 1 | K2454: =G2454-I2454 -> 0 | M2454: =SUMIFS(Ere!C:C,Ere!B:B,A2454) -> 0 | N2454: =F2454-M2454 -> 1 | O2454: {=XLOOKUP(A2454,Data!F:F,Data!O:O)} -> 0.79 | P2454: =+O2454*2.5 -> 1.98
A2455: 25045-J3B-J044-T2C1-001 | B2455: {=XLOOKUP(A2455,Data!F:F,Data!G:G)} -> J3B | C2455: =MID(A2455,11,4) -> J044 | D2455: {=XLOOKUP(A2455,Data!F:F,Data!C:C)} -> EXT | E2455: {=XLOOKUP(A2455,Data!F:F,Data!H:H)} | F2455: =SUMIFS(Data!J:J,Data!F:F,A2455) -> 1 | G2455: =SUMIFS(Cast!C:C,CastElements,A2455) -> 0 | H2455: =F2455-G2455 -> 1 | I2455: =SUMIFS(Del!C:C,Del!B:B,A2455) -> 0 | J2455: =F2455-I2455 -> 1 | K2455: =G2455-I2455 -> 0 | M2455: =SUMIFS(Ere!C:C,Ere!B:B,A2455) -> 0 | N2455: =F2455-M2455 -> 1 | O2455: {=XLOOKUP(A2455,Data!F:F,Data!O:O)} -> 0.79 | P2455: =+O2455*2.5 -> 1.98
A2456: 25045-J3B-J045-T2C1-001 | B2456: {=XLOOKUP(A2456,Data!F:F,Data!G:G)} -> J3B | C2456: =MID(A2456,11,4) -> J045 | D2456: {=XLOOKUP(A2456,Data!F:F,Data!C:C)} -> EXT | E2456: {=XLOOKUP(A2456,Data!F:F,Data!H:H)} | F2456: =SUMIFS(Data!J:J,Data!F:F,A2456) -> 1 | G2456: =SUMIFS(Cast!C:C,CastElements,A2456) -> 0 | H2456: =F2456-G2456 -> 1 | I2456: =SUMIFS(Del!C:C,Del!B:B,A2456) -> 0 | J2456: =F2456-I2456 -> 1 | K2456: =G2456-I2456 -> 0 | M2456: =SUMIFS(Ere!C:C,Ere!B:B,A2456) -> 0 | N2456: =F2456-M2456 -> 1 | O2456: {=XLOOKUP(A2456,Data!F:F,Data!O:O)} -> 0.79 | P2456: =+O2456*2.5 -> 1.98
A2457: 25045-J3B-J046-T2C1-001 | B2457: {=XLOOKUP(A2457,Data!F:F,Data!G:G)} -> J3B | C2457: =MID(A2457,11,4) -> J046 | D2457: {=XLOOKUP(A2457,Data!F:F,Data!C:C)} -> EXT | E2457: {=XLOOKUP(A2457,Data!F:F,Data!H:H)} | F2457: =SUMIFS(Data!J:J,Data!F:F,A2457) -> 1 | G2457: =SUMIFS(Cast!C:C,CastElements,A2457) -> 0 | H2457: =F2457-G2457 -> 1 | I2457: =SUMIFS(Del!C:C,Del!B:B,A2457) -> 0 | J2457: =F2457-I2457 -> 1 | K2457: =G2457-I2457 -> 0 | M2457: =SUMIFS(Ere!C:C,Ere!B:B,A2457) -> 0 | N2457: =F2457-M2457 -> 1 | O2457: {=XLOOKUP(A2457,Data!F:F,Data!O:O)} -> 0.79 | P2457: =+O2457*2.5 -> 1.98
A2458: 25045-J3B-J041-T2C5-001 | B2458: {=XLOOKUP(A2458,Data!F:F,Data!G:G)} -> J3B | C2458: =MID(A2458,11,4) -> J041 | D2458: {=XLOOKUP(A2458,Data!F:F,Data!C:C)} | E2458: {=XLOOKUP(A2458,Data!F:F,Data!H:H)} | F2458: =SUMIFS(Data!J:J,Data!F:F,A2458) -> 1 | G2458: =SUMIFS(Cast!C:C,CastElements,A2458) -> 0 | H2458: =F2458-G2458 -> 1 | I2458: =SUMIFS(Del!C:C,Del!B:B,A2458) -> 0 | J2458: =F2458-I2458 -> 1 | K2458: =G2458-I2458 -> 0 | M2458: =SUMIFS(Ere!C:C,Ere!B:B,A2458) -> 0 | N2458: =F2458-M2458 -> 1 | O2458: {=XLOOKUP(A2458,Data!F:F,Data!O:O)} -> 1.29 | P2458: =+O2458*2.5 -> 3.23
A2459: 25045-J3B-J041-T2C5-002 | B2459: {=XLOOKUP(A2459,Data!F:F,Data!G:G)} -> J3B | C2459: =MID(A2459,11,4) -> J041 | D2459: {=XLOOKUP(A2459,Data!F:F,Data!C:C)} | E2459: {=XLOOKUP(A2459,Data!F:F,Data!H:H)} | F2459: =SUMIFS(Data!J:J,Data!F:F,A2459) -> 1 | G2459: =SUMIFS(Cast!C:C,CastElements,A2459) -> 0 | H2459: =F2459-G2459 -> 1 | I2459: =SUMIFS(Del!C:C,Del!B:B,A2459) -> 0 | J2459: =F2459-I2459 -> 1 | K2459: =G2459-I2459 -> 0 | M2459: =SUMIFS(Ere!C:C,Ere!B:B,A2459) -> 0 | N2459: =F2459-M2459 -> 1 | O2459: {=XLOOKUP(A2459,Data!F:F,Data!O:O)} -> 1.34 | P2459: =+O2459*2.5 -> 3.35
A2460: 25045-J3B-J041-T2C9-001 | B2460: {=XLOOKUP(A2460,Data!F:F,Data!G:G)} -> J3B | C2460: =MID(A2460,11,4) -> J041 | D2460: {=XLOOKUP(A2460,Data!F:F,Data!C:C)} | E2460: {=XLOOKUP(A2460,Data!F:F,Data!H:H)} | F2460: =SUMIFS(Data!J:J,Data!F:F,A2460) -> 1 | G2460: =SUMIFS(Cast!C:C,CastElements,A2460) -> 0 | H2460: =F2460-G2460 -> 1 | I2460: =SUMIFS(Del!C:C,Del!B:B,A2460) -> 0 | J2460: =F2460-I2460 -> 1 | K2460: =G2460-I2460 -> 0 | M2460: =SUMIFS(Ere!C:C,Ere!B:B,A2460) -> 0 | N2460: =F2460-M2460 -> 1 | O2460: {=XLOOKUP(A2460,Data!F:F,Data!O:O)} -> 1.84 | P2460: =+O2460*2.5 -> 4.60
A2461: 25045-J3B-J041-T3C5-001 | B2461: {=XLOOKUP(A2461,Data!F:F,Data!G:G)} -> J3B | C2461: =MID(A2461,11,4) -> J041 | D2461: {=XLOOKUP(A2461,Data!F:F,Data!C:C)} | E2461: {=XLOOKUP(A2461,Data!F:F,Data!H:H)} | F2461: =SUMIFS(Data!J:J,Data!F:F,A2461) -> 1 | G2461: =SUMIFS(Cast!C:C,CastElements,A2461) -> 0 | H2461: =F2461-G2461 -> 1 | I2461: =SUMIFS(Del!C:C,Del!B:B,A2461) -> 0 | J2461: =F2461-I2461 -> 1 | K2461: =G2461-I2461 -> 0 | M2461: =SUMIFS(Ere!C:C,Ere!B:B,A2461) -> 0 | N2461: =F2461-M2461 -> 1 | O2461: {=XLOOKUP(A2461,Data!F:F,Data!O:O)} | P2461: =+O2461*2.5 -> -
A2462: 25045-J3B-J041-T3C5-002 | B2462: {=XLOOKUP(A2462,Data!F:F,Data!G:G)} -> J3B | C2462: =MID(A2462,11,4) -> J041 | D2462: {=XLOOKUP(A2462,Data!F:F,Data!C:C)} | E2462: {=XLOOKUP(A2462,Data!F:F,Data!H:H)} | F2462: =SUMIFS(Data!J:J,Data!F:F,A2462) -> 1 | G2462: =SUMIFS(Cast!C:C,CastElements,A2462) -> 0 | H2462: =F2462-G2462 -> 1 | I2462: =SUMIFS(Del!C:C,Del!B:B,A2462) -> 0 | J2462: =F2462-I2462 -> 1 | K2462: =G2462-I2462 -> 0 | M2462: =SUMIFS(Ere!C:C,Ere!B:B,A2462) -> 0 | N2462: =F2462-M2462 -> 1 | O2462: {=XLOOKUP(A2462,Data!F:F,Data!O:O)} -> 2.12 | P2462: =+O2462*2.5 -> 5.30
A2463: 25045-J3B-J041-T3C5-003 | B2463: {=XLOOKUP(A2463,Data!F:F,Data!G:G)} -> J3B | C2463: =MID(A2463,11,4) -> J041 | D2463: {=XLOOKUP(A2463,Data!F:F,Data!C:C)} | E2463: {=XLOOKUP(A2463,Data!F:F,Data!H:H)} | F2463: =SUMIFS(Data!J:J,Data!F:F,A2463) -> 1 | G2463: =SUMIFS(Cast!C:C,CastElements,A2463) -> 0 | H2463: =F2463-G2463 -> 1 | I2463: =SUMIFS(Del!C:C,Del!B:B,A2463) -> 0 | J2463: =F2463-I2463 -> 1 | K2463: =G2463-I2463 -> 0 | M2463: =SUMIFS(Ere!C:C,Ere!B:B,A2463) -> 0 | N2463: =F2463-M2463 -> 1 | O2463: {=XLOOKUP(A2463,Data!F:F,Data!O:O)} -> 2.12 | P2463: =+O2463*2.5 -> 5.30
A2464: 25045-J3B-J041-T3C5-004 | B2464: {=XLOOKUP(A2464,Data!F:F,Data!G:G)} -> J3B | C2464: =MID(A2464,11,4) -> J041 | D2464: {=XLOOKUP(A2464,Data!F:F,Data!C:C)} | E2464: {=XLOOKUP(A2464,Data!F:F,Data!H:H)} | F2464: =SUMIFS(Data!J:J,Data!F:F,A2464) -> 1 | G2464: =SUMIFS(Cast!C:C,CastElements,A2464) -> 0 | H2464: =F2464-G2464 -> 1 | I2464: =SUMIFS(Del!C:C,Del!B:B,A2464) -> 0 | J2464: =F2464-I2464 -> 1 | K2464: =G2464-I2464 -> 0 | M2464: =SUMIFS(Ere!C:C,Ere!B:B,A2464) -> 0 | N2464: =F2464-M2464 -> 1 | O2464: {=XLOOKUP(A2464,Data!F:F,Data!O:O)} -> 2.12 | P2464: =+O2464*2.5 -> 5.30
A2465: 25045-J3B-J041-T3C5-005 | B2465: {=XLOOKUP(A2465,Data!F:F,Data!G:G)} -> J3B | C2465: =MID(A2465,11,4) -> J041 | D2465: {=XLOOKUP(A2465,Data!F:F,Data!C:C)} | E2465: {=XLOOKUP(A2465,Data!F:F,Data!H:H)} | F2465: =SUMIFS(Data!J:J,Data!F:F,A2465) -> 1 | G2465: =SUMIFS(Cast!C:C,CastElements,A2465) -> 0 | H2465: =F2465-G2465 -> 1 | I2465: =SUMIFS(Del!C:C,Del!B:B,A2465) -> 0 | J2465: =F2465-I2465 -> 1 | K2465: =G2465-I2465 -> 0 | M2465: =SUMIFS(Ere!C:C,Ere!B:B,A2465) -> 0 | N2465: =F2465-M2465 -> 1 | O2465: {=XLOOKUP(A2465,Data!F:F,Data!O:O)} -> 2.26 | P2465: =+O2465*2.5 -> 5.65
... A2572: 25045-J3B-J047-T7C1-001 | B2572: {=XLOOKUP(A2572,Data!F:F,Data!G:G)} -> J3B | C2572: =MID(A2572,11,4) -> J047 | D2572: {=XLOOKUP(A2572,Data!F:F,Data!C:C)} | E2572: {=XLOOKUP(A2572,Data!F:F,Data!H:H)} | F2572: =SUMIFS(Data!J:J,Data!F:F,A2572) -> 0 | G2572: =SUMIFS(Cast!C:C,CastElements,A2572) -> 0 | H2572: =F2572-G2572 -> 0 | I2572: =SUMIFS(Del!C:C,Del!B:B,A2572) -> 0 | J2572: =F2572-I2572 -> 0 | K2572: =G2572-I2572 -> 0 | M2572: =SUMIFS(Ere!C:C,Ere!B:B,A2572) -> 0 | N2572: =F2572-M2572 -> 0 | O2572: {=XLOOKUP(A2572,Data!F:F,Data!O:O)} | P2572: =+O2572*2.5 -> -

Sheet Location_Summary
M2: Data date as of | O2: =+Summary!N2 -> 08-May-26
A4: P25045 - ACRES BW Progress Status (Element pc wise)
A5: Location | B5: Zone | C5: Villa | D5: Reqd.Qty | E5: Issued Qty | F5: Cast Qty | G5: Remain to Cast Qty | H5: %Cast | I5: Deliver Qty | J5: Remain to Deliver Qty | K5: %Del | L5: Factory stock | M5: Install Qty | N5: Remain to Install | O5: %Install | P5: Remarks | Q5: Balance to issue
A6: EXT | B6: J1B | C6: J123 | D6: =SUMIFS('Element wise-detail Summary'!F:F,'Element wise-detail Summary'!B:B,Location_Summary!B6,'Element wise-detail Summary'!C:C,Location_Summary!C6,'Element wise-detail Summary'!D:D,Location_Summary!A6) -> 7 | E6: =SUMIFS('Element wise-detail Summary'!$F$3:$F$1048576,'Element wise-detail Summary'!$B$3:$B$1048576,Location_Summary!$B6,'Element wise-detail Summary'!$C$3:$C$1048576,Location_Summary!C6,'Element wise-detail Summary'!$D$3:$D$1048576,Location_Summary!A6) -> 7 | F6: =SUMIFS('Element wise-detail Summary'!$G$3:$G$1048576,'Element wise-detail Summary'!$B$3:$B$1048576,Location_Summary!$B6,'Element wise-detail Summary'!$C$3:$C$1048576,Location_Summary!C6,'Element wise-detail Summary'!$D$3:$D$1048576,Location_Summary!A6) -> 7 | G6: =E6-F6 -> 0 | H6: =F6/D6 -> 100% | I6: =SUMIFS('Element wise-detail Summary'!$I$3:$I$1048576,'Element wise-detail Summary'!$B$3:$B$1048576,B6,'Element wise-detail Summary'!$C$3:$C$1048576,C6,'Element wise-detail Summary'!$D$3:$D$1048576,Location_Summary!A6) -> 7 | J6: =E6-I6 -> 0 | K6: =I6/D6 -> 100% | L6: =F6-I6 -> 0 | M6: =SUMIFS('Element wise-detail Summary'!$M$3:$M$1048576,'Element wise-detail Summary'!$B$3:$B$1048576,B6,'Element wise-detail Summary'!$C$3:$C$1048576,C6,'Element wise-detail Summary'!$D$3:$D$1048576,Location_Summary!A6) -> 7 | N6: =E6-M6 -> 0 | O6: =M6/D6 -> 100% | Q6: =+D6-E6 -> 0
A7: EXT | B7: J1B | C7: J124 | D7: =SUMIFS('Element wise-detail Summary'!F:F,'Element wise-detail Summary'!B:B,Location_Summary!B7,'Element wise-detail Summary'!C:C,Location_Summary!C7,'Element wise-detail Summary'!D:D,Location_Summary!A7) -> 9 | E7: =SUMIFS('Element wise-detail Summary'!$F$3:$F$1048576,'Element wise-detail Summary'!$B$3:$B$1048576,Location_Summary!$B7,'Element wise-detail Summary'!$C$3:$C$1048576,Location_Summary!C7,'Element wise-detail Summary'!$D$3:$D$1048576,Location_Summary!A7) -> 9 | F7: =SUMIFS('Element wise-detail Summary'!$G$3:$G$1048576,'Element wise-detail Summary'!$B$3:$B$1048576,Location_Summary!$B7,'Element wise-detail Summary'!$C$3:$C$1048576,Location_Summary!C7,'Element wise-detail Summary'!$D$3:$D$1048576,Location_Summary!A7) -> 9 | G7: =E7-F7 -> 0 | H7: =F7/D7 -> 100% | I7: =SUMIFS('Element wise-detail Summary'!$I$3:$I$1048576,'Element wise-detail Summary'!$B$3:$B$1048576,B7,'Element wise-detail Summary'!$C$3:$C$1048576,C7,'Element wise-detail Summary'!$D$3:$D$1048576,Location_Summary!A7) -> 9 | J7: =E7-I7 -> 0 | K7: =I7/D7 -> 100% | L7: =F7-I7 -> 0 | M7: =SUMIFS('Element wise-detail Summary'!$M$3:$M$1048576,'Element wise-detail Summary'!$B$3:$B$1048576,B7,'Element wise-detail Summary'!$C$3:$C$1048576,C7,'Element wise-detail Summary'!$D$3:$D$1048576,Location_Summary!A7) -> 9 | N7: =E7-M7 -> 0 | O7: =M7/D7 -> 100% | Q7: =+D7-E7 -> 0
A8: EXT | B8: J1B | C8: J125 | D8: =SUMIFS('Element wise-detail Summary'!F:F,'Element wise-detail Summary'!B:B,Location_Summary!B8,'Element wise-detail Summary'!C:C,Location_Summary!C8,'Element wise-detail Summary'!D:D,Location_Summary!A8) -> 8 | E8: =SUMIFS('Element wise-detail Summary'!$F$3:$F$1048576,'Element wise-detail Summary'!$B$3:$B$1048576,Location_Summary!$B8,'Element wise-detail Summary'!$C$3:$C$1048576,Location_Summary!C8,'Element wise-detail Summary'!$D$3:$D$1048576,Location_Summary!A8) -> 8 | F8: =SUMIFS('Element wise-detail Summary'!$G$3:$G$1048576,'Element wise-detail Summary'!$B$3:$B$1048576,Location_Summary!$B8,'Element wise-detail Summary'!$C$3:$C$1048576,Location_Summary!C8,'Element wise-detail Summary'!$D$3:$D$1048576,Location_Summary!A8) -> 8 | G8: =E8-F8 -> 0 | H8: =F8/D8 -> 100% | I8: =SUMIFS('Element wise-detail Summary'!$I$3:$I$1048576,'Element wise-detail Summary'!$B$3:$B$1048576,B8,'Element wise-detail Summary'!$C$3:$C$1048576,C8,'Element wise-detail Summary'!$D$3:$D$1048576,Location_Summary!A8) -> 8 | J8: =E8-I8 -> 0 | K8: =I8/D8 -> 100% | L8: =F8-I8 -> 0 | M8: =SUMIFS('Element wise-detail Summary'!$M$3:$M$1048576,'Element wise-detail Summary'!$B$3:$B$1048576,B8,'Element wise-detail Summary'!$C$3:$C$1048576,C8,'Element wise-detail Summary'!$D$3:$D$1048576,Location_Summary!A8) -> 8 | N8: =E8-M8 -> 0 | O8: =M8/D8 -> 100% | Q8: =+D8-E8 -> 0
A9: EXT | B9: J1B | C9: J126 | D9: =SUMIFS('Element wise-detail Summary'!F:F,'Element wise-detail Summary'!B:B,Location_Summary!B9,'Element wise-detail Summary'!C:C,Location_Summary!C9,'Element wise-detail Summary'!D:D,Location_Summary!A9) -> 4 | E9: =SUMIFS('Element wise-detail Summary'!$F$3:$F$1048576,'Element wise-detail Summary'!$B$3:$B$1048576,Location_Summary!$B9,'Element wise-detail Summary'!$C$3:$C$1048576,Location_Summary!C9,'Element wise-detail Summary'!$D$3:$D$1048576,Location_Summary!A9) -> 4 | F9: =SUMIFS('Element wise-detail Summary'!$G$3:$G$1048576,'Element wise-detail Summary'!$B$3:$B$1048576,Location_Summary!$B9,'Element wise-detail Summary'!$C$3:$C$1048576,Location_Summary!C9,'Element wise-detail Summary'!$D$3:$D$1048576,Location_Summary!A9) -> 4 | G9: =E9-F9 -> 0 | H9: =F9/D9 -> 100% | I9: =SUMIFS('Element wise-detail Summary'!$I$3:$I$1048576,'Element wise-detail Summary'!$B$3:$B$1048576,B9,'Element wise-detail Summary'!$C$3:$C$1048576,C9,'Element wise-detail Summary'!$D$3:$D$1048576,Location_Summary!A9) -> 0 | J9: =E9-I9 -> 4 | K9: =I9/D9 -> 0% | L9: =F9-I9 -> 4 | M9: =SUMIFS('Element wise-detail Summary'!$M$3:$M$1048576,'Element wise-detail Summary'!$B$3:$B$1048576,B9,'Element wise-detail Summary'!$C$3:$C$1048576,C9,'Element wise-detail Summary'!$D$3:$D$1048576,Location_Summary!A9) -> 0 | N9: =E9-M9 -> 4 | O9: =M9/D9 -> 0% | Q9: =+D9-E9 -> 0
A10: EXT | B10: J1B | C10: J127 | D10: =SUMIFS('Element wise-detail Summary'!F:F,'Element wise-detail Summary'!B:B,Location_Summary!B10,'Element wise-detail Summary'!C:C,Location_Summary!C10,'Element wise-detail Summary'!D:D,Location_Summary!A10) -> 4 | E10: =SUMIFS('Element wise-detail Summary'!$F$3:$F$1048576,'Element wise-detail Summary'!$B$3:$B$1048576,Location_Summary!$B10,'Element wise-detail Summary'!$C$3:$C$1048576,Location_Summary!C10,'Element wise-detail Summary'!$D$3:$D$1048576,Location_Summary!A10) -> 4 | F10: =SUMIFS('Element wise-detail Summary'!$G$3:$G$1048576,'Element wise-detail Summary'!$B$3:$B$1048576,Location_Summary!$B10,'Element wise-detail Summary'!$C$3:$C$1048576,Location_Summary!C10,'Element wise-detail Summary'!$D$3:$D$1048576,Location_Summary!A10) -> 4 | G10: =E10-F10 -> 0 | H10: =F10/D10 -> 100% | I10: =SUMIFS('Element wise-detail Summary'!$I$3:$I$1048576,'Element wise-detail Summary'!$B$3:$B$1048576,B10,'Element wise-detail Summary'!$C$3:$C$1048576,C10,'Element wise-detail Summary'!$D$3:$D$1048576,Location_Summary!A10) -> 0 | J10: =E10-I10 -> 4 | K10: =I10/D10 -> 0% | L10: =F10-I10 -> 4 | M10: =SUMIFS('Element wise-detail Summary'!$M$3:$M$1048576,'Element wise-detail Summary'!$B$3:$B$1048576,B10,'Element wise-detail Summary'!$C$3:$C$1048576,C10,'Element wise-detail Summary'!$D$3:$D$1048576,Location_Summary!A10) -> 0 | N10: =E10-M10 -> 4 | O10: =M10/D10 -> 0% | Q10: =+D10-E10 -> 0
A11: EXT | B11: J1B | C11: J128 | D11: =SUMIFS('Element wise-detail Summary'!F:F,'Element wise-detail Summary'!B:B,Location_Summary!B11,'Element wise-detail Summary'!C:C,Location_Summary!C11,'Element wise-detail Summary'!D:D,Location_Summary!A11) -> 4 | E11: =SUMIFS('Element wise-detail Summary'!$F$3:$F$1048576,'Element wise-detail Summary'!$B$3:$B$1048576,Location_Summary!$B11,'Element wise-detail Summary'!$C$3:$C$1048576,Location_Summary!C11,'Element wise-detail Summary'!$D$3:$D$1048576,Location_Summary!A11) -> 4 | F11: =SUMIFS('Element wise-detail Summary'!$G$3:$G$1048576,'Element wise-detail Summary'!$B$3:$B$1048576,Location_Summary!$B11,'Element wise-detail Summary'!$C$3:$C$1048576,Location_Summary!C11,'Element wise-detail Summary'!$D$3:$D$1048576,Location_Summary!A11) -> 4 | G11: =E11-F11 -> 0 | H11: =F11/D11 -> 100% | I11: =SUMIFS('Element wise-detail Summary'!$I$3:$I$1048576,'Element wise-detail Summary'!$B$3:$B$1048576,B11,'Element wise-detail Summary'!$C$3:$C$1048576,C11,'Element wise-detail Summary'!$D$3:$D$1048576,Location_Summary!A11) -> 0 | J11: =E11-I11 -> 4 | K11: =I11/D11 -> 0% | L11: =F11-I11 -> 4 | M11: =SUMIFS('Element wise-detail Summary'!$M$3:$M$1048576,'Element wise-detail Summary'!$B$3:$B$1048576,B11,'Element wise-detail Summary'!$C$3:$C$1048576,C11,'Element wise-detail Summary'!$D$3:$D$1048576,Location_Summary!A11) -> 0 | N11: =E11-M11 -> 4 | O11: =M11/D11 -> 0% | Q11: =+D11-E11 -> 0
