Workbook

Sheet Detail Summary
M2: Data date as of | N2: 46149
A4: P25034-Amara BW Progress Status (Element pc wise)-BW
A5: Product | B5: Zone | C5: Estd Reqd.Qty | D5: Issued Qty | E5: Cast Qty | F5: Remain to Cast Qty | G5: %Cast | H5: Deliver Qty | I5: Remain to Deliver Qty | J5: %Del | K5: Factory stock | L5: Ere Qty | M5: Remain to Erec Qty | N5: %Erect | O5: Remarks | P5: ENGG
A6: BW | B6: MOCKUP | C6: 28 | D6: =SUMIFS('Element wise-detail Summary'!$F:$F,'Element wise-detail Summary'!$D:$D,'Detail Summary'!$A6,'Element wise-detail Summary'!$C:$C,'Detail Summary'!$B6) -> 28 | E6: =SUMIFS(Cast!$C:$C,Cast!$E:$E,$B6) -> 28 | F6: =D6-E6 -> 0 | G6: =E6/C6 -> 1 | H6: =SUMIFS(Del!$C:$C,Del!$E:$E,'Detail Summary'!$B6) -> 28 | I6: =D6-H6 -> 0 | J6: =H6/C6 -> 1 | K6: =E6-H6 -> 0 | L6: =SUMIFS(Ere!$C:$C,Ere!$E:$E,'Detail Summary'!$B6) -> 28 | M6: =D6-L6 -> 0 | N6: =L6/C6 -> 1 | P6: 1
A7: BW | B7: Zone-1 | C7: 149 | D7: =SUMIFS('Element wise-detail Summary'!$F:$F,'Element wise-detail Summary'!$D:$D,'Detail Summary'!$A7,'Element wise-detail Summary'!$C:$C,'Detail Summary'!$B7) -> 149 | E7: =SUMIFS(Cast!$C:$C,Cast!$E:$E,$B7) -> 148 | F7: =D7-E7 -> 1 | G7: =E7/C7 -> 0.99328859 | H7: =SUMIFS(Del!$C:$C,Del!$E:$E,'Detail Summary'!$B7) -> 145 | I7: =D7-H7 -> 4 | J7: =H7/C7 -> 0.97315436 | K7: =E7-H7 -> 3 | L7: =SUMIFS(Ere!$C:$C,Ere!$E:$E,'Detail Summary'!$B7) -> 142 | M7: =D7-L7 -> 7 | N7: =L7/C7 -> 0.95302013 | P7: 1
A8: BW | B8: Zone-2 | C8: 73 | D8: =SUMIFS('Element wise-detail Summary'!$F:$F,'Element wise-detail Summary'!$D:$D,'Detail Summary'!$A8,'Element wise-detail Summary'!$C:$C,'Detail Summary'!$B8) -> 73 | E8: =SUMIFS(Cast!$C:$C,Cast!$E:$E,$B8) -> 73 | F8: =D8-E8 -> 0 | G8: =E8/C8 -> 1 | H8: =SUMIFS(Del!$C:$C,Del!$E:$E,'Detail Summary'!$B8) -> 73 | I8: =D8-H8 -> 0 | J8: =H8/C8 -> 1 | K8: =E8-H8 -> 0 | L8: =SUMIFS(Ere!$C:$C,Ere!$E:$E,'Detail Summary'!$B8) -> 72 | M8: =D8-L8 -> 1 | N8: =L8/C8 -> 0.98630137 | P8: 1
A9: BW | B9: Zone-4 | C9: 158 | D9: =SUMIFS('Element wise-detail Summary'!$F:$F,'Element wise-detail Summary'!$D:$D,'Detail Summary'!$A9,'Element wise-detail Summary'!$C:$C,'Detail Summary'!$B9) -> 158 | E9: =SUMIFS(Cast!$C:$C,Cast!$E:$E,$B9) -> 158 | F9: =D9-E9 -> 0 | G9: =E9/C9 -> 1 | H9: =SUMIFS(Del!$C:$C,Del!$E:$E,'Detail Summary'!$B9) -> 146 | I9: =D9-H9 -> 12 | J9: =H9/C9 -> 0.92405063 | K9: =E9-H9 -> 12 | L9: =SUMIFS(Ere!$C:$C,Ere!$E:$E,'Detail Summary'!$B9) -> 149 | M9: =D9-L9 -> 9 | N9: =L9/C9 -> 0.94303797 | P9: 0.6
A10: BW | B10: Zone-3 | C10: 116 | D10: =SUMIFS('Element wise-detail Summary'!$F:$F,'Element wise-detail Summary'!$D:$D,'Detail Summary'!$A10,'Element wise-detail Summary'!$C:$C,'Detail Summary'!$B10) -> 116 | E10: =SUMIFS(Cast!$C:$C,Cast!$E:$E,$B10) -> 116 | F10: =D10-E10 -> 0 | G10: =E10/C10 -> 1 | H10: =SUMIFS(Del!$C:$C,Del!$E:$E,'Detail Summary'!$B10) -> 22 | I10: =D10-H10 -> 94 | J10: =H10/C10 -> 0.18965517 | K10: =E10-H10 -> 94 | L10: =SUMIFS(Ere!$C:$C,Ere!$E:$E,'Detail Summary'!$B10) -> 22 | M10: =D10-L10 -> 94 | N10: =L10/C10 -> 0.18965517 | P10: 1
A11: BW | B11: Zone-5 | C11: 147 | D11: =SUMIFS('Element wise-detail Summary'!$F:$F,'Element wise-detail Summary'!$D:$D,'Detail Summary'!$A11,'Element wise-detail Summary'!$C:$C,'Detail Summary'!$B11) -> 147 | E11: =SUMIFS(Cast!$C:$C,Cast!$E:$E,$B11) -> 147 | F11: =D11-E11 -> 0 | G11: =E11/C11 -> 1 | H11: =SUMIFS(Del!$C:$C,Del!$E:$E,'Detail Summary'!$B11) -> 56 | I11: =D11-H11 -> 91 | J11: =H11/C11 -> 0.38095238 | K11: =E11-H11 -> 91 | L11: =SUMIFS(Ere!$C:$C,Ere!$E:$E,'Detail Summary'!$B11) -> 53 | M11: =D11-L11 -> 94 | N11: =L11/C11 -> 0.36054422 | P11: 1
A12: BW | B12: Zone-6 | C12: 182 | D12: =SUMIFS('Element wise-detail Summary'!$F:$F,'Element wise-detail Summary'!$D:$D,'Detail Summary'!$A12,'Element wise-detail Summary'!$C:$C,'Detail Summary'!$B12) -> 182 | E12: =SUMIFS(Cast!$C:$C,Cast!$E:$E,$B12) -> 182 | F12: =D12-E12 -> 0 | G12: =E12/C12 -> 1 | H12: =SUMIFS(Del!$C:$C,Del!$E:$E,'Detail Summary'!$B12) -> 144 | I12: =D12-H12 -> 38 | J12: =H12/C12 -> 0.79120879 | K12: =E12-H12 -> 38 | L12: =SUMIFS(Ere!$C:$C,Ere!$E:$E,'Detail Summary'!$B12) -> 115 | M12: =D12-L12 -> 67 | N12: =L12/C12 -> 0.63186813 | P12: 1
A13: BW | B13: Zone-7 | C13: 148 | D13: =SUMIFS('Element wise-detail Summary'!$F:$F,'Element wise-detail Summary'!$D:$D,'Detail Summary'!$A13,'Element wise-detail Summary'!$C:$C,'Detail Summary'!$B13) -> 148 | E13: =SUMIFS(Cast!$C:$C,Cast!$E:$E,$B13) -> 148 | F13: =D13-E13 -> 0 | G13: =E13/C13 -> 1 | H13: =SUMIFS(Del!$C:$C,Del!$E:$E,'Detail Summary'!$B13) -> 21 | I13: =D13-H13 -> 127 | J13: =H13/C13 -> 0.14189189 | K13: =E13-H13 -> 127 | L13: =SUMIFS(Ere!$C:$C,Ere!$E:$E,'Detail Summary'!$B13) -> 0 | M13: =D13-L13 -> 148 | N13: =L13/C13 -> 0 | P13: 1
A14: BW | B14: Zone-8 | C14: 110 | D14: =SUMIFS('Element wise-detail Summary'!$F:$F,'Element wise-detail Summary'!$D:$D,'Detail Summary'!$A14,'Element wise-detail Summary'!$C:$C,'Detail Summary'!$B14) -> 110 | E14: =SUMIFS(Cast!$C:$C,Cast!$E:$E,$B14) -> 110 | F14: =D14-E14 -> 0 | G14: =E14/C14 -> 1 | H14: =SUMIFS(Del!$C:$C,Del!$E:$E,'Detail Summary'!$B14) -> 0 | I14: =D14-H14 -> 110 | J14: =H14/C14 -> 0 | K14: =E14-H14 -> 110 | L14: =SUMIFS(Ere!$C:$C,Ere!$E:$E,'Detail Summary'!$B14) -> 0 | M14: =D14-L14 -> 110 | N14: =L14/C14 -> 0 | P14: 0.6
A15: Total | C15: =SUM(C6:C14) -> 1111 | D15: =SUM(D6:D14) -> 1111 | E15: =SUM(E6:E14) -> 1110 | F15: =SUM(F6:F14) -> 1 | G15: =E15/C15 -> 0.99909991 | H15: =SUM(H6:H14) -> 635 | I15: =SUM(I6:I14) -> 476 | J15: =H15/C15 -> 0.57155716 | K15: =SUM(K6:K14) -> 475 | L15: =SUM(L6:L14) -> 581 | M15: =SUM(M6:M14) -> 530 | N15: =L15/C15 -> 0.5229523

Sheet BW
B1: SR.NO | C1: ELEMENT ID | D1: ZONE | E1: VILLA | F1: WIDTH | G1: HEIGHT | H1: THK | I1: TYPE | J1: FOOTING SIZE | K1: COL LOCATION | L1: DIST.NO | M1: DWG ISSUE DATE | N1: REV | O1: REV DATE | P1: VOL | Q1: WT | R1: SA-RECESS | S1: SB-RECESS | T1: PLANNED DATE | U1: CASTING DATE | V1: BAY | W1: PALLET | X1: REMARK | Y1: Column1 | Z1: Column2 | AA1: Column3 | AB1: Column4
B2: 1 | C2: ZA3-M1-16-B1-C4-01 | D2: A3 | E2: X267 | F2: 3930 | G2: 2950 | H2: 120 | I2: CFC | J2: 250*1000*1400 | L2: 006 | M2: 45789 | N2: 0 | P2: 1.468 | Q2: =+P2*2.5 -> 3.67 | T2: 45792 | U2: 45792 | V2: 21 | W2: 34B | AA2: WIR
B3: 2 | C3: A3-M1-16-A03-C1-04 | D3: A3 | E3: X267 | F3: 400 | G3: 3160 | H3: 300 | I3: EFC | J3: 250*1400*1200 | K3: BC | L3: 003 | M3: 45787 | N3: 0 | P3: 0.761 | Q3: =+P3*2.5 -> 1.9025 | T3: 45794 | U3: 45794 | V3: 21 | W3: 09B | AA3: WIR
B4: 3 | C4: A3-M1-16-A03-C1-05 | D4: A3 | E4: X267 | F4: 400 | G4: 3160 | H4: 300 | I4: EFC | J4: 250*1400*1200 | K4: BC | L4: 003 | M4: 45787 | N4: 0 | P4: 0.761 | Q4: =+P4*2.5 -> 1.9025 | T4: 45794 | U4: 45794 | V4: 21 | W4: 09A | AA4: WIR
B5: 4 | C5: A3-M1-16-A03-C1-06 | D5: A3 | E5: X267 | F5: 400 | G5: 3160 | H5: 300 | I5: EFC | J5: 250*1400*1200 | K5: BC | L5: 003 | M5: 45787 | N5: 0 | P5: 0.764 | Q5: =+P5*2.5 -> 1.91 | T5: 45794 | U5: 45794 | V5: 21 | W5: 18B | AA5: WIR
B6: 5 | C6: A3-M1-16-A03-C1-03 | D6: A3 | E6: X267 | F6: 400 | G6: 3160 | H6: 300 | I6: EFC | J6: 250*1500*1200 | K6: BC | L6: 007 | M6: 45789 | N6: 1 | O6: 45789 | P6: 0.791 | Q6: =+P6*2.5 -> 1.9775 | T6: 45794 | U6: 45794 | V6: 21 | W6: 19A | AA6: WIR
B7: 6 | C7: A3-M1-16-A03-C1-01 | D7: A3 | E7: X267 | F7: 400 | G7: 3160 | H7: 300 | I7: EFC | J7: 250*1600*1300 | K7: LLC | L7: 007 | M7: 45789 | N7: 0 | P7: 0.867 | Q7: =+P7*2.5 -> 2.1675 | T7: 45805 | U7: 45805 | V7: 21 | W7: 06A | AA7: WIR
B8: 7 | C8: A3-M1-16-A03-C1-P01 | D8: A3 | E8: X267 | F8: 4948 | G8: 2710 | H8: 120 | I8: P | J8: - | L8: 001/004 | M8: 45785 | N8: 1 | O8: 45787 | P8: 1.609 | Q8: =+P8*2.5 -> 4.0225 | T8: 45793 | U8: 45793 | V8: 21 | W8: 33A | AA8: WIR
B9: 8 | C9: A3-M1-16-A03-C1-P02 | D9: A3 | E9: X267 | F9: 4948 | G9: 1670 | H9: 120 | I9: P | J9: - | L9: 001/004 | M9: 45785 | N9: 1 | O9: 45787 | P9: 0.992 | Q9: =+P9*2.5 -> 2.48 | T9: 45792 | U9: 45792 | V9: 21 | W9: 34C | AA9: WIR
B10: 9 | C10: A3-M1-16-A03-C2-P01 | D10: A3 | E10: X267 | F10: 4217 | G10: 670 | H10: 120 | I10: P | J10: - | L10: 001/004 | M10: 45785 | N10: 1 | O10: 45787 | P10: 0.845 | Q10: =+P10*2.5 -> 2.1125 | T10: 45792 | U10: 45792 | V10: 21 | W10: 34D | AA10: WIR
B11: 10 | C11: A3-M1-16-A03-C2-P02 | D11: A3 | E11: X267 | F11: 4217 | G11: 670 | H11: 120 | I11: P | J11: - | L11: 001/004 | M11: 45785 | N11: 1 | O11: 45787 | P11: 0.845 | Q11: =+P11*2.5 -> 2.1125 | T11: 45793 | U11: 45793 | V11: 21 | W11: 33B | AA11: WIR
B12: 11 | C12: A3-M1-16-A03-C2-P03 | D12: A3 | E12: X267 | F12: 4217 | G12: 670 | H12: 120 | I12: P | J12: - | L12: 001/004 | M12: 45785 | N12: 1 | O12: 45787 | P12: 0.845 | Q12: =+P12*2.5 -> 2.1125 | T12: 45793 | U12: 45793 | V12: 21 | W12: 33C | AA12: WIR
B13: 12 | C13: ZA3-M1-16-B1-C3-01 | D13: A3 | E13: X266 | F13: 4322 | G13: 2950 | H13: 120 | I13: CFC | J13: 250*1000*1400 | L13: 006 | M13: 45789 | N13: 0 | P13: 1.57 | Q13: =+P13*2.5 -> 3.925 | T13: 45792 | U13: 45792 | V13: 21 | W13: 38B | AA13: WIR
B14: 13 | C14: ZA3-M1-16-B1-C4-02 | D14: A3 | E14: X265 | F14: 3935 | G14: 2950 | H14: 120 | I14: CFC | J14: 250*1000*1400 | L14: 006 | M14: 45789 | N14: 0 | P14: 1.469 | Q14: =+P14*2.5 -> 3.6725 | T14: 45792 | U14: 45792 | V14: 21 | W14: 38A | AA14: WIR
B15: 14 | C15: ZA3-M1-16-B1-C3-02 | D15: A3 | E15: X264 | F15: 4245 | G15: 2950 | H15: 120 | I15: CFC | J15: 250*1000*1400 | L15: 006 | M15: 45789 | N15: 0 | P15: 1.55 | Q15: =+P15*2.5 -> 3.875 | T15: 45792 | U15: 45792 | V15: 21 | W15: 34A | AA15: WIR
B16: 15 | C16: ZA3-M1-16-B1-C4-03 | D16: A3 | E16: X263 | F16: 3780 | G16: 2950 | H16: 120 | I16: CFC | J16: 250*1000*1400 | L16: 006 | M16: 45789 | N16: 0 | P16: 1.429 | Q16: =+P16*2.5 -> 3.5725 | T16: 45793 | U16: 45793 | V16: 21 | W16: 37A | AA16: WIR
B17: 16 | C17: ZA3-M1-15-B3-C1-01 | D17: A3 | E17: X261 | F17: 4780 | G17: 3250 | H17: 120 | I17: CFC | J17: 250*1000*1400 | L17: 006 | M17: 45789 | N17: 0 | P17: 1.905 | Q17: =+P17*2.5 -> 4.7625 | T17: 45794 | U17: 45794 | V17: 21 | W17: 34B | AA17: WIR
B18: 17 | C18: ZA3-M1-15-B3-C1-02 | D18: A3 | E18: X261 | F18: 4780 | G18: 3250 | H18: 120 | I18: CFC | J18: 250*1000*1400 | L18: 006 | M18: 45789 | N18: 0 | P18: 1.905 | Q18: =+P18*2.5 -> 4.7625 | T18: 45793 | U18: 45793 | V18: 21 | W18: 38B | AA18: WIR
B19: 18 | C19: ZA3-M1-15-B3-C1-03 | D19: A3 | E19: X261 | F19: 4780 | G19: 3250 | H19: 120 | I19: CFC | J19: 250*1000*1400 | L19: 006 | M19: 45789 | N19: 0 | P19: 1.905 | Q19: =+P19*2.5 -> 4.7625 | T19: 45793 | U19: 45793 | V19: 21 | W19: 38A | AA19: WIR
B20: 19 | C20: ZA3-M1-15-B3-C1-04 | D20: A3 | E20: X261 | F20: 4780 | G20: 3250 | H20: 120 | I20: CFC | J20: 250*1000*1400 | L20: 006 | M20: 45789 | N20: 0 | P20: 1.905 | Q20: =+P20*2.5 -> 4.7625 | T20: 45793 | U20: 45793 | V20: 21 | W20: 34A | AA20: WIR
B21: 20 | C21: ZA3-M1-15-B3-C1-05 | D21: A3 | E21: X261 | F21: 4770 | G21: 3250 | H21: 120 | I21: CFC | J21: 250*1000*1400 | L21: 006 | M21: 45789 | N21: 0 | P21: 1.902 | Q21: =+P21*2.5 -> 4.755 | T21: 45796 | U21: 45796 | V21: 21 | W21: 38B | AA21: WIR
B22: 21 | C22: ZA3-M1-15-B1-C4-01 | D22: A3 | E22: X261 | F22: 3930 | G22: 2950 | H22: 120 | I22: CFC | J22: 250*1000*1400 | L22: 006 | M22: 45789 | N22: 0 | P22: 1.468 | Q22: =+P22*2.5 -> 3.67 | T22: 45796 | U22: 45796 | V22: 21 | W22: 33B | AA22: WIR
B23: 22 | C23: ZA3-M1-15-B1-C3-01 | D23: A3 | E23: X260 | F23: 4320 | G23: 2950 | H23: 120 | I23: CFC | J23: 250*1000*1400 | L23: 006 | M23: 45789 | N23: 0 | P23: 1.57 | Q23: =+P23*2.5 -> 3.925 | T23: 45796 | U23: 45796 | V23: 21 | W23: 38A | AA23: WIR
B24: 23 | C24: ZA3-M1-15-B1-C4-02 | D24: A3 | E24: X259 | F24: 3930 | G24: 2950 | H24: 120 | I24: CFC | J24: 250*1000*1400 | L24: 006 | M24: 45789 | N24: 0 | P24: 1.468 | Q24: =+P24*2.5 -> 3.67 | T24: 45796 | U24: 45796 | V24: 21 | W24: 34A | AA24: WIR
... B28: 27 | C28: ZA3-M1-15-B1-C4-04 | D28: A3 | E28: X255 | F28: 3688 | G28: 2950 | H28: 120 | I28: CFC | J28: 250*1000*1400 | L28: 006 | M28: 45789 | N28: 0 | P28: 1.405 | Q28: =+P28*2.5 -> 3.5125 | T28: 45797 | U28: 45797 | V28: 21 | W28: 38A | AA28: WIR
B29: 28 | C29: A3-M1-15-A02-C1-03 | D29: A3 | E29: X254 | F29: 400 | G29: 2790 | H29: 300 | I29: EFC | J29: 200*1150*1200 | K29: BC | L29: 003 | M29: 45787 | N29: 0 | P29: 0.651 | Q29: =+P29*2.5 -> 1.6275 | T29: 45796 | U29: 45796 | V29: 21 | W29: 18B | AA29: WIR
B30: 29 | C30: A3-M1-15-A02-C1-02 | D30: A3 | E30: X254 | F30: 400 | G30: 2790 | H30: 300 | I30: EFC | J30: 250*1100*1200 | K30: BC | L30: 003 | M30: 45787 | N30: 0 | P30: 0.634 | Q30: =+P30*2.5 -> 1.585 | T30: 45796 | U30: 45796 | V30: 21 | W30: 09A | AA30: WIR
B31: 30 | C31: A3-M1-15-A02-C1-01 | D31: A3 | E31: X254 | F31: 400 | G31: 2920 | H31: 300 | I31: EFC | J31: 250*1400*1200 | K31: BC | L31: 003 | M31: 45787 | N31: 0 | P31: 0.737 | Q31: =+P31*2.5 -> 1.8425 | T31: 45796 | U31: 45796 | V31: 21 | W31: 09B | AA31: WIR
B32: 31 | C32: A3-M1-15-A02-C1-05 | D32: A3 | E32: X254 | F32: 400 | G32: 2630 | H32: 300 | I32: EFC | J32: 250*1300*1200 | K32: RLC | L32: 007 | M32: 45789 | N32: 0 | P32: 0.68 | Q32: =+P32*2.5 -> 1.7 | T32: 45803 | U32: 45803 | V32: 21 | W32: 06A | AA32: WIR
B33: 32 | C33: A3-M1-15-A02-C1-P01A | D33: A3 | E33: X254 | F33: 5084 | G33: 2180 | H33: 120 | I33: P | J33: - | L33: 001/004 | M33: 45785 | N33: 1 | O33: 45787 | P33: 1.33 | Q33: =+P33*2.5 -> 3.325 | T33: 45794 | U33: 45794 | V33: 21 | W33: 30A | AA33: WIR
B34: 33 | C34: A3-M1-15-A02-C1-P01 | D34: A3 | E34: X254 | F34: 5083 | G34: 1310 | H34: 120 | I34: P | J34: - | L34: 002 | M34: 45785 | N34: 0 | P34: 0.797 | Q34: =+P34*2.5 -> 1.9925 | T34: 45794 | U34: 45794 | V34: 21 | W34: 28B | AA34: WIR
B35: 34 | C35: A3-M1-15-A02-C2-P01 | D35: A3 | E35: X254 | F35: 4132 | G35: 1440 | H35: 120 | I35: P | J35: - | L35: 001/004 | M35: 45785 | N35: 1 | O35: 45787 | P35: 0.714 | Q35: =+P35*2.5 -> 1.785 | T35: 45794 | U35: 45794 | V35: 21 | W35: 28A | AA35: WIR
B36: 35 | C36: A3-M1-15-A02-C2-P02 | D36: A3 | E36: X254 | F36: 4131 | G36: 1440 | H36: 120 | I36: P | J36: - | L36: 001/004 | M36: 45785 | N36: 1 | O36: 45787 | P36: 0.712 | Q36: =+P36*2.5 -> 1.78 | T36: 45796 | U36: 45796 | V36: 21 | W36: 28C | AA36: WIR
B37: 36 | C37: A3-M1-15-A02-C2-P02A | D37: A3 | E37: X254 | F37: 4131 | G37: 1310 | H37: 120 | I37: P | J37: - | L37: 002 | M37: 45785 | N37: 0 | P37: 0.649 | Q37: =+P37*2.5 -> 1.6225 | T37: 45796 | U37: 45796 | V37: 21 | W37: 28D | AA37: WIR
B38: 37 | C38: ZA3-M1-22-B5-C1-04 | D38: A3 | E38: X302 | F38: 4406 | G38: 3730 | H38: 120 | I38: CFC | J38: 250*1000*1600 | L38: 006 | M38: 45789 | N38: 0 | P38: 2.196 | Q38: =+P38*2.5 -> 5.49 | T38: 45794 | U38: 45794 | V38: 21 | W38: 29B | AA38: WIR
B39: 38 | C39: ZA3-M1-22-B5-C5-01 | D39: A3 | E39: X302 | F39: 4406 | G39: 3730 | H39: 120 | I39: CFC | J39: 250*1000*1600 | L39: 006 | M39: 45789 | N39: 0 | P39: 2.196 | Q39: =+P39*2.5 -> 5.49 | T39: 45797 | U39: 45797 | V39: 21 | W39: 37A | AA39: WIR
B40: 39 | C40: A3-M1-22-A02-C1-06 | D40: A3 | E40: X302 | F40: 400 | G40: 3480 | H40: 300 | I40: EFC | J40: 250*1100*1200 | K40: BC | L40: 007 | M40: 45789 | N40: 1 | O40: 45789 | P40: 0.695 | Q40: =+P40*2.5 -> 1.7375 | T40: 45797 | U40: 45797 | V40: 21 | W40: 18B | AA40: WIR
B41: 40 | C41: A3-M1-22-A02-C1-03 | D41: A3 | E41: X302 | F41: 400 | G41: 2860 | H41: 300 | I41: EFC | J41: 250*1150*1200 | K41: BC | L41: 007 | M41: 45789 | N41: 1 | O41: 45789 | P41: 0.656 | Q41: =+P41*2.5 -> 1.64 | T41: 45797 | U41: 45797 | V41: 21 | W41: 19A | AA41: WIR
B42: 41 | C42: A3-M1-22-A02-C1-04 | D42: A3 | E42: X302 | F42: 400 | G42: 3170 | H42: 300 | I42: EFC | J42: 250*1100*1200 | K42: BC | L42: 006 | M42: 45789 | N42: 0 | P42: 0.674 | Q42: =+P42*2.5 -> 1.685 | T42: 45797 | U42: 45797 | V42: 21 | W42: 09B | AA42: WIR
B43: 42 | C43: A3-M1-22-A02-C1-05 | D43: A3 | E43: X302 | F43: 400 | G43: 3170 | H43: 300 | I43: EFC | J43: 250*1400*1200 | K43: BC | L43: 006 | M43: 45789 | N43: 0 | P43: 0.761 | Q43: =+P43*2.5 -> 1.9025 | T43: 45798 | U43: 45798 | V43: 21 | W43: 09A | AA43: WIR
...

Sheet Element wise-detail Summary
E1: =SUBTOTAL(9,E3:E1048576) -> 16.2 | F1: =SUBTOTAL(9,F3:F1048576) -> 9 | G1: =SUBTOTAL(9,G3:G1048576) -> 9 | H1: =SUBTOTAL(9,H3:H1048576) -> 0 | I1: =SUBTOTAL(9,I3:I1048576) -> 6 | J1: =SUBTOTAL(9,J3:J1048576) -> 3 | K1: =SUBTOTAL(9,K3:K1048576) -> 3 | L1: =SUBTOTAL(9,L3:L1048576) -> 4 | ... N1: =SUBTOTAL(9,N3:N1048576) -> 11.611
A2: Element ID | B2: Villa No. | C2: Zone | D2: Product | E2: m3/pc | F2: Issued Qty | G2: Cast Qty | H2: Remain to Cast | I2: Deliver Qty | J2: Remain to Deliver | K2: Factory stock | L2: Install | M2: Remain to Install | Q2: Mock up
A3: AMR-V17-T1C10-001 | B3: =VLOOKUP(A3,'AFC Data details'!$B:$E,4,0) -> V17 | C3: =_xlfn.XLOOKUP(A3,'AFC Data details'!$B:$B,'AFC Data details'!$D:$D) -> MOCKUP | D3: BW | E3: =VLOOKUP(A3,'AFC Data details'!$B:$P,15,0) -> 1.787 | F3: =SUMIFS('AFC Data details'!C:C,'AFC Data details'!$B:$B,'Element wise-detail Summary'!$A3) -> 1 | G3: =SUMIFS(Cast!$C:$C,Cast!$B:$B,'Element wise-detail Summary'!$A3) -> 1 | H3: =F3-G3 -> 0 | I3: =SUMIFS(Del!$C:$C,Del!$B:$B,'Element wise-detail Summary'!$A3) -> 1 | J3: =F3-I3 -> 0 | K3: =G3-I3 -> 0 | L3: =SUMIF(Ere!$B:$B,'Element wise-detail Summary'!$A3,Ere!$C:$C) -> 1 | M3: =F3-L3 -> 0 | N3: =I3*E3 -> 1.787 | Q3: Zone-1
A4: AMR-V17-T1C10-002 | B4: =VLOOKUP(A4,'AFC Data details'!$B:$E,4,0) -> V17 | C4: =_xlfn.XLOOKUP(A4,'AFC Data details'!$B:$B,'AFC Data details'!$D:$D) -> MOCKUP | D4: BW | E4: =VLOOKUP(A4,'AFC Data details'!$B:$P,15,0) -> 1.779 | F4: =SUMIFS('AFC Data details'!C:C,'AFC Data details'!$B:$B,'Element wise-detail Summary'!$A4) -> 1 | G4: =SUMIFS(Cast!$C:$C,Cast!$B:$B,'Element wise-detail Summary'!$A4) -> 1 | H4: =F4-G4 -> 0 | I4: =SUMIFS(Del!$C:$C,Del!$B:$B,'Element wise-detail Summary'!$A4) -> 1 | J4: =F4-I4 -> 0 | K4: =G4-I4 -> 0 | L4: =SUMIF(Ere!$B:$B,'Element wise-detail Summary'!$A4,Ere!$C:$C) -> 1 | M4: =F4-L4 -> 0 | N4: =I4*E4 -> 1.779 | Q4: Zone-2
A5: AMR-V17-T1C10-003 | B5: =VLOOKUP(A5,'AFC Data details'!$B:$E,4,0) -> V17 | C5: =_xlfn.XLOOKUP(A5,'AFC Data details'!$B:$B,'AFC Data details'!$D:$D) -> MOCKUP | D5: BW | E5: =VLOOKUP(A5,'AFC Data details'!$B:$P,15,0) -> 1.779 | F5: =SUMIFS('AFC Data details'!C:C,'AFC Data details'!$B:$B,'Element wise-detail Summary'!$A5) -> 1 | G5: =SUMIFS(Cast!$C:$C,Cast!$B:$B,'Element wise-detail Summary'!$A5) -> 1 | H5: =F5-G5 -> 0 | I5: =SUMIFS(Del!$C:$C,Del!$B:$B,'Element wise-detail Summary'!$A5) -> 1 | J5: =F5-I5 -> 0 | K5: =G5-I5 -> 0 | L5: =SUMIF(Ere!$B:$B,'Element wise-detail Summary'!$A5,Ere!$C:$C) -> 1 | M5: =F5-L5 -> 0 | N5: =I5*E5 -> 1.779 | Q5: Zone-3
A6: AMR-V17-T1C11-002 | B6: =VLOOKUP(A6,'AFC Data details'!$B:$E,4,0) -> V17 | C6: =_xlfn.XLOOKUP(A6,'AFC Data details'!$B:$B,'AFC Data details'!$D:$D) -> MOCKUP | D6: BW | E6: =VLOOKUP(A6,'AFC Data details'!$B:$P,15,0) -> 1.894 | F6: =SUMIFS('AFC Data details'!C:C,'AFC Data details'!$B:$B,'Element wise-detail Summary'!$A6) -> 1 | G6: =SUMIFS(Cast!$C:$C,Cast!$B:$B,'Element wise-detail Summary'!$A6) -> 1 | H6: =F6-G6 -> 0 | I6: =SUMIFS(Del!$C:$C,Del!$B:$B,'Element wise-detail Summary'!$A6) -> 1 | J6: =F6-I6 -> 0 | K6: =G6-I6 -> 0 | L6: =SUMIF(Ere!$B:$B,'Element wise-detail Summary'!$A6,Ere!$C:$C) -> 1 | M6: =F6-L6 -> 0 | N6: =I6*E6 -> 1.894 | Q6: Zone-5
A7: AMR-V17-T1C11-001 | B7: =VLOOKUP(A7,'AFC Data details'!$B:$E,4,0) -> V17 | C7: =_xlfn.XLOOKUP(A7,'AFC Data details'!$B:$B,'AFC Data details'!$D:$D) -> MOCKUP | D7: BW | E7: =VLOOKUP(A7,'AFC Data details'!$B:$P,15,0) -> 1.894 | F7: =SUMIFS('AFC Data details'!C:C,'AFC Data details'!$B:$B,'Element wise-detail Summary'!$A7) -> 1 | G7: =SUMIFS(Cast!$C:$C,Cast!$B:$B,'Element wise-detail Summary'!$A7) -> 1 | H7: =F7-G7 -> 0 | I7: =SUMIFS(Del!$C:$C,Del!$B:$B,'Element wise-detail Summary'!$A7) -> 1 | J7: =F7-I7 -> 0 | K7: =G7-I7 -> 0 | L7: =SUMIF(Ere!$B:$B,'Element wise-detail Summary'!$A7,Ere!$C:$C) -> 1 | M7: =F7-L7 -> 0 | N7: =I7*E7 -> 1.894
A8: AMR-V17-T1C11-003 | B8: =VLOOKUP(A8,'AFC Data details'!$B:$E,4,0) -> V17 | C8: =_xlfn.XLOOKUP(A8,'AFC Data details'!$B:$B,'AFC Data details'!$D:$D) -> MOCKUP | D8: BW | E8: =VLOOKUP(A8,'AFC Data details'!$B:$P,15,0) -> 1.977 | F8: =SUMIFS('AFC Data details'!C:C,'AFC Data details'!$B:$B,'Element wise-detail Summary'!$A8) -> 1 | G8: =SUMIFS(Cast!$C:$C,Cast!$B:$B,'Element wise-detail Summary'!$A8) -> 1 | H8: =F8-G8 -> 0 | I8: =SUMIFS(Del!$C:$C,Del!$B:$B,'Element wise-detail Summary'!$A8) -> 1 | J8: =F8-I8 -> 0 | K8: =G8-I8 -> 0 | L8: =SUMIF(Ere!$B:$B,'Element wise-detail Summary'!$A8,Ere!$C:$C) -> 1 | M8: =F8-L8 -> 0 | N8: =I8*E8 -> 1.977
A9: AMR-V17-T1C12-001 | B9: =VLOOKUP(A9,'AFC Data details'!$B:$E,4,0) -> V17 | C9: =_xlfn.XLOOKUP(A9,'AFC Data details'!$B:$B,'AFC Data details'!$D:$D) -> MOCKUP | D9: BW | E9: =VLOOKUP(A9,'AFC Data details'!$B:$P,15,0) -> 2.138 | F9: =SUMIFS('AFC Data details'!C:C,'AFC Data details'!$B:$B,'Element wise-detail Summary'!$A9) -> 1 | G9: =SUMIFS(Cast!$C:$C,Cast!$B:$B,'Element wise-detail Summary'!$A9) -> 1 | H9: =F9-G9 -> 0 | I9: =SUMIFS(Del!$C:$C,Del!$B:$B,'Element wise-detail Summary'!$A9) -> 1 | J9: =F9-I9 -> 0 | K9: =G9-I9 -> 0 | L9: =SUMIF(Ere!$B:$B,'Element wise-detail Summary'!$A9,Ere!$C:$C) -> 1 | M9: =F9-L9 -> 0 | N9: =I9*E9 -> 2.138
A10: AMR-V17-T1C13-001 | B10: =VLOOKUP(A10,'AFC Data details'!$B:$E,4,0) -> V17 | C10: =_xlfn.XLOOKUP(A10,'AFC Data details'!$B:$B,'AFC Data details'!$D:$D) -> MOCKUP | D10: BW | E10: =VLOOKUP(A10,'AFC Data details'!$B:$P,15,0) -> 1.991 | F10: =SUMIFS('AFC Data details'!C:C,'AFC Data details'!$B:$B,'Element wise-detail Summary'!$A10) -> 1 | G10: =SUMIFS(Cast!$C:$C,Cast!$B:$B,'Element wise-detail Summary'!$A10) -> 1 | H10: =F10-G10 -> 0 | I10: =SUMIFS(Del!$C:$C,Del!$B:$B,'Element wise-detail Summary'!$A10) -> 1 | J10: =F10-I10 -> 0 | K10: =G10-I10 -> 0 | L10: =SUMIF(Ere!$B:$B,'Element wise-detail Summary'!$A10,Ere!$C:$C) -> 1 | M10: =F10-L10 -> 0 | N10: =I10*E10 -> 1.991
A11: AMR-V17-T1C16-001 | B11: =VLOOKUP(A11,'AFC Data details'!$B:$E,4,0) -> V17 | C11: =_xlfn.XLOOKUP(A11,'AFC Data details'!$B:$B,'AFC Data details'!$D:$D) -> MOCKUP | D11: BW | E11: =VLOOKUP(A11,'AFC Data details'!$B:$P,15,0) -> 2.216 | F11: =SUMIFS('AFC Data details'!C:C,'AFC Data details'!$B:$B,'Element wise-detail Summary'!$A11) -> 1 | G11: =SUMIFS(Cast!$C:$C,Cast!$B:$B,'Element wise-detail Summary'!$A11) -> 1 | H11: =F11-G11 -> 0 | I11: =SUMIFS(Del!$C:$C,Del!$B:$B,'Element wise-detail Summary'!$A11) -> 1 | J11: =F11-I11 -> 0 | K11: =G11-I11 -> 0 | L11: =SUMIF(Ere!$B:$B,'Element wise-detail Summary'!$A11,Ere!$C:$C) -> 1 | M11: =F11-L11 -> 0 | N11: =I11*E11 -> 2.216
A12: AMR-V17-T2C1-001 | B12: =VLOOKUP(A12,'AFC Data details'!$B:$E,4,0) -> V17 | C12: =_xlfn.XLOOKUP(A12,'AFC Data details'!$B:$B,'AFC Data details'!$D:$D) -> MOCKUP | D12: BW | E12: =VLOOKUP(A12,'AFC Data details'!$B:$P,15,0) -> 1.413 | F12: =SUMIFS('AFC Data details'!C:C,'AFC Data details'!$B:$B,'Element wise-detail Summary'!$A12) -> 1 | G12: =SUMIFS(Cast!$C:$C,Cast!$B:$B,'Element wise-detail Summary'!$A12) -> 1 | H12: =F12-G12 -> 0 | I12: =SUMIFS(Del!$C:$C,Del!$B:$B,'Element wise-detail Summary'!$A12) -> 1 | J12: =F12-I12 -> 0 | K12: =G12-I12 -> 0 | L12: =SUMIF(Ere!$B:$B,'Element wise-detail Summary'!$A12,Ere!$C:$C) -> 1 | M12: =F12-L12 -> 0 | N12: =I12*E12 -> 1.413
A13: AMR-V17-T3C6-001 | B13: =VLOOKUP(A13,'AFC Data details'!$B:$E,4,0) -> V17 | C13: =_xlfn.XLOOKUP(A13,'AFC Data details'!$B:$B,'AFC Data details'!$D:$D) -> MOCKUP | D13: BW | E13: =VLOOKUP(A13,'AFC Data details'!$B:$P,15,0) -> 1.69 | F13: =SUMIFS('AFC Data details'!C:C,'AFC Data details'!$B:$B,'Element wise-detail Summary'!$A13) -> 1 | G13: =SUMIFS(Cast!$C:$C,Cast!$B:$B,'Element wise-detail Summary'!$A13) -> 1 | H13: =F13-G13 -> 0 | I13: =SUMIFS(Del!$C:$C,Del!$B:$B,'Element wise-detail Summary'!$A13) -> 1 | J13: =F13-I13 -> 0 | K13: =G13-I13 -> 0 | L13: =SUMIF(Ere!$B:$B,'Element wise-detail Summary'!$A13,Ere!$C:$C) -> 1 | M13: =F13-L13 -> 0 | N13: =I13*E13 -> 1.69
A14: AMR-V17-T3C6-002 | B14: =VLOOKUP(A14,'AFC Data details'!$B:$E,4,0) -> V17 | C14: =_xlfn.XLOOKUP(A14,'AFC Data details'!$B:$B,'AFC Data details'!$D:$D) -> MOCKUP | D14: BW | E14: =VLOOKUP(A14,'AFC Data details'!$B:$P,15,0) -> 1.69 | F14: =SUMIFS('AFC Data details'!C:C,'AFC Data details'!$B:$B,'Element wise-detail Summary'!$A14) -> 1 | G14: =SUMIFS(Cast!$C:$C,Cast!$B:$B,'Element wise-detail Summary'!$A14) -> 1 | H14: =F14-G14 -> 0 | I14: =SUMIFS(Del!$C:$C,Del!$B:$B,'Element wise-detail Summary'!$A14) -> 1 | J14: =F14-I14 -> 0 | K14: =G14-I14 -> 0 | L14: =SUMIF(Ere!$B:$B,'Element wise-detail Summary'!$A14,Ere!$C:$C) -> 1 | M14: =F14-L14 -> 0 | N14: =I14*E14 -> 1.69
A15: AMR-V17-T3C6-003 | B15: =VLOOKUP(A15,'AFC Data details'!$B:$E,4,0) -> V17 | C15: =_xlfn.XLOOKUP(A15,'AFC Data details'!$B:$B,'AFC Data details'!$D:$D) -> MOCKUP | D15: BW | E15: =VLOOKUP(A15,'AFC Data details'!$B:$P,15,0) -> 1.862 | F15: =SUMIFS('AFC Data details'!C:C,'AFC Data details'!$B:$B,'Element wise-detail Summary'!$A15) -> 1 | G15: =SUMIFS(Cast!$C:$C,Cast!$B:$B,'Element wise-detail Summary'!$A15) -> 1 | H15: =F15-G15 -> 0 | I15: =SUMIFS(Del!$C:$C,Del!$B:$B,'Element wise-detail Summary'!$A15) -> 1 | J15: =F15-I15 -> 0 | K15: =G15-I15 -> 0 | L15: =SUMIF(Ere!$B:$B,'Element wise-detail Summary'!$A15,Ere!$C:$C) -> 1 | M15: =F15-L15 -> 0 | N15: =I15*E15 -> 1.862
A16: AMR-V18-T1C3-001 | B16: =VLOOKUP(A16,'AFC Data details'!$B:$E,4,0) -> V18 | C16: =_xlfn.XLOOKUP(A16,'AFC Data details'!$B:$B,'AFC Data details'!$D:$D) -> MOCKUP | D16: BW | E16: =VLOOKUP(A16,'AFC Data details'!$B:$P,15,0) -> 1.251 | F16: =SUMIFS('AFC Data details'!C:C,'AFC Data details'!$B:$B,'Element wise-detail Summary'!$A16) -> 1 | G16: =SUMIFS(Cast!$C:$C,Cast!$B:$B,'Element wise-detail Summary'!$A16) -> 1 | H16: =F16-G16 -> 0 | I16: =SUMIFS(Del!$C:$C,Del!$B:$B,'Element wise-detail Summary'!$A16) -> 1 | J16: =F16-I16 -> 0 | K16: =G16-I16 -> 0 | L16: =SUMIF(Ere!$B:$B,'Element wise-detail Summary'!$A16,Ere!$C:$C) -> 1 | M16: =F16-L16 -> 0 | N16: =I16*E16 -> 1.251
A17: AMR-V18-T1C10-001 | B17: =VLOOKUP(A17,'AFC Data details'!$B:$E,4,0) -> V18 | C17: =_xlfn.XLOOKUP(A17,'AFC Data details'!$B:$B,'AFC Data details'!$D:$D) -> MOCKUP | D17: BW | E17: =VLOOKUP(A17,'AFC Data details'!$B:$P,15,0) -> 1.595 | F17: =SUMIFS('AFC Data details'!C:C,'AFC Data details'!$B:$B,'Element wise-detail Summary'!$A17) -> 1 | G17: =SUMIFS(Cast!$C:$C,Cast!$B:$B,'Element wise-detail Summary'!$A17) -> 1 | H17: =F17-G17 -> 0 | I17: =SUMIFS(Del!$C:$C,Del!$B:$B,'Element wise-detail Summary'!$A17) -> 1 | J17: =F17-I17 -> 0 | K17: =G17-I17 -> 0 | L17: =SUMIF(Ere!$B:$B,'Element wise-detail Summary'!$A17,Ere!$C:$C) -> 1 | M17: =F17-L17 -> 0 | N17: =I17*E17 -> 1.595
A18: AMR-V18-T1C10-002 | B18: =VLOOKUP(A18,'AFC Data details'!$B:$E,4,0) -> V18 | C18: =_xlfn.XLOOKUP(A18,'AFC Data details'!$B:$B,'AFC Data details'!$D:$D) -> MOCKUP | D18: BW | E18: =VLOOKUP(A18,'AFC Data details'!$B:$P,15,0) -> 1.617 | F18: =SUMIFS('AFC Data details'!C:C,'AFC Data details'!$B:$B,'Element wise-detail Summary'!$A18) -> 1 | G18: =SUMIFS(Cast!$C:$C,Cast!$B:$B,'Element wise-detail Summary'!$A18) -> 1 | H18: =F18-G18 -> 0 | I18: =SUMIFS(Del!$C:$C,Del!$B:$B,'Element wise-detail Summary'!$A18) -> 1 | J18: =F18-I18 -> 0 | K18: =G18-I18 -> 0 | L18: =SUMIF(Ere!$B:$B,'Element wise-detail Summary'!$A18,Ere!$C:$C) -> 1 | M18: =F18-L18 -> 0 | N18: =I18*E18 -> 1.617
... A30: AMR-V18-T3C6-001 | B30: =VLOOKUP(A30,'AFC Data details'!$B:$E,4,0) -> V18 | C30: =_xlfn.XLOOKUP(A30,'AFC Data details'!$B:$B,'AFC Data details'!$D:$D) -> MOCKUP | D30: BW | E30: =VLOOKUP(A30,'AFC Data details'!$B:$P,15,0) -> 1.858 | F30: =SUMIFS('AFC Data details'!C:C,'AFC Data details'!$B:$B,'Element wise-detail Summary'!$A30) -> 1 | G30: =SUMIFS(Cast!$C:$C,Cast!$B:$B,'Element wise-detail Summary'!$A30) -> 1 | H30: =F30-G30 -> 0 | I30: =SUMIFS(Del!$C:$C,Del!$B:$B,'Element wise-detail Summary'!$A30) -> 1 | J30: =F30-I30 -> 0 | K30: =G30-I30 -> 0 | L30: =SUMIF(Ere!$B:$B,'Element wise-detail Summary'!$A30,Ere!$C:$C) -> 1 | M30: =F30-L30 -> 0 | N30: =I30*E30 -> 1.858
A31: AZ1-V19-T1C10-001 | B31: =VLOOKUP(A31,'AFC Data details'!$B:$E,4,0) -> V19 | C31: Zone-1 | D31: BW | E31: =VLOOKUP(A31,'AFC Data details'!$B:$P,15,0) -> 1.33 | F31: =SUMIFS('AFC Data details'!C:C,'AFC Data details'!$B:$B,'Element wise-detail Summary'!$A31) -> 1 | G31: =SUMIFS(Cast!$C:$C,Cast!$B:$B,'Element wise-detail Summary'!$A31) -> 1 | H31: =F31-G31 -> 0 | I31: =SUMIFS(Del!$C:$C,Del!$B:$B,'Element wise-detail Summary'!$A31) -> 1 | J31: =F31-I31 -> 0 | K31: =G31-I31 -> 0 | L31: =SUMIF(Ere!$B:$B,'Element wise-detail Summary'!$A31,Ere!$C:$C) -> 1 | M31: =F31-L31 -> 0 | N31: =I31*E31 -> 1.33
A32: AZ1-V19-T1C10-002 | B32: =VLOOKUP(A32,'AFC Data details'!$B:$E,4,0) -> V19 | C32: Zone-1 | D32: BW | E32: =VLOOKUP(A32,'AFC Data details'!$B:$P,15,0) -> 1.33 | F32: =SUMIFS('AFC Data details'!C:C,'AFC Data details'!$B:$B,'Element wise-detail Summary'!$A32) -> 1 | G32: =SUMIFS(Cast!$C:$C,Cast!$B:$B,'Element wise-detail Summary'!$A32) -> 1 | H32: =F32-G32 -> 0 | I32: =SUMIFS(Del!$C:$C,Del!$B:$B,'Element wise-detail Summary'!$A32) -> 1 | J32: =F32-I32 -> 0 | K32: =G32-I32 -> 0 | L32: =SUMIF(Ere!$B:$B,'Element wise-detail Summary'!$A32,Ere!$C:$C) -> 1 | M32: =F32-L32 -> 0 | N32: =I32*E32 -> 1.33
A33: AZ1-V19-T1C10-003 | B33: =VLOOKUP(A33,'AFC Data details'!$B:$E,4,0) -> V19 | C33: Zone-1 | D33: BW | E33: =VLOOKUP(A33,'AFC Data details'!$B:$P,15,0) -> 1.73 | F33: =SUMIFS('AFC Data details'!C:C,'AFC Data details'!$B:$B,'Element wise-detail Summary'!$A33) -> 1 | G33: =SUMIFS(Cast!$C:$C,Cast!$B:$B,'Element wise-detail Summary'!$A33) -> 1 | H33: =F33-G33 -> 0 | I33: =SUMIFS(Del!$C:$C,Del!$B:$B,'Element wise-detail Summary'!$A33) -> 1 | J33: =F33-I33 -> 0 | K33: =G33-I33 -> 0 | L33: =SUMIF(Ere!$B:$B,'Element wise-detail Summary'!$A33,Ere!$C:$C) -> 1 | M33: =F33-L33 -> 0 | N33: =I33*E33 -> 1.73
A34: AZ1-V19-T1C11-001 | B34: =VLOOKUP(A34,'AFC Data details'!$B:$E,4,0) -> V19 | C34: Zone-1 | D34: BW | E34: =VLOOKUP(A34,'AFC Data details'!$B:$P,15,0) -> 1.949 | F34: =SUMIFS('AFC Data details'!C:C,'AFC Data details'!$B:$B,'Element wise-detail Summary'!$A34) -> 1 | G34: =SUMIFS(Cast!$C:$C,Cast!$B:$B,'Element wise-detail Summary'!$A34) -> 1 | H34: =F34-G34 -> 0 | I34: =SUMIFS(Del!$C:$C,Del!$B:$B,'Element wise-detail Summary'!$A34) -> 1 | J34: =F34-I34 -> 0 | K34: =G34-I34 -> 0 | L34: =SUMIF(Ere!$B:$B,'Element wise-detail Summary'!$A34,Ere!$C:$C) -> 1 | M34: =F34-L34 -> 0 | N34: =I34*E34 -> 1.949
A35: AZ1-V19-T1C12S-001 | B35: =VLOOKUP(A35,'AFC Data details'!$B:$E,4,0) -> V19 | C35: Zone-1 | D35: BW | E35: =VLOOKUP(A35,'AFC Data details'!$B:$P,15,0) -> 2.508 | F35: =SUMIFS('AFC Data details'!C:C,'AFC Data details'!$B:$B,'Element wise-detail Summary'!$A35) -> 1 | G35: =SUMIFS(Cast!$C:$C,Cast!$B:$B,'Element wise-detail Summary'!$A35) -> 1 | H35: =F35-G35 -> 0 | I35: =SUMIFS(Del!$C:$C,Del!$B:$B,'Element wise-detail Summary'!$A35) -> 1 | J35: =F35-I35 -> 0 | K35: =G35-I35 -> 0 | L35: =SUMIF(Ere!$B:$B,'Element wise-detail Summary'!$A35,Ere!$C:$C) -> 0 | M35: =F35-L35 -> 1 | N35: =I35*E35 -> 2.508
A36: AZ1-V19-T1C15S-001 | B36: =VLOOKUP(A36,'AFC Data details'!$B:$E,4,0) -> V19 | C36: Zone-1 | D36: BW | E36: =VLOOKUP(A36,'AFC Data details'!$B:$P,15,0) -> 2.848 | F36: =SUMIFS('AFC Data details'!C:C,'AFC Data details'!$B:$B,'Element wise-detail Summary'!$A36) -> 1 | G36: =SUMIFS(Cast!$C:$C,Cast!$B:$B,'Element wise-detail Summary'!$A36) -> 1 | H36: =F36-G36 -> 0 | I36: =SUMIFS(Del!$C:$C,Del!$B:$B,'Element wise-detail Summary'!$A36) -> 1 | J36: =F36-I36 -> 0 | K36: =G36-I36 -> 0 | L36: =SUMIF(Ere!$B:$B,'Element wise-detail Summary'!$A36,Ere!$C:$C) -> 1 | M36: =F36-L36 -> 0 | N36: =I36*E36 -> 2.848
A37: AZ1-V19-T1C15S-002 | B37: =VLOOKUP(A37,'AFC Data details'!$B:$E,4,0) -> V19 | C37: Zone-1 | D37: BW | E37: =VLOOKUP(A37,'AFC Data details'!$B:$P,15,0) -> 2.923 | F37: =SUMIFS('AFC Data details'!C:C,'AFC Data details'!$B:$B,'Element wise-detail Summary'!$A37) -> 1 | G37: =SUMIFS(Cast!$C:$C,Cast!$B:$B,'Element wise-detail Summary'!$A37) -> 1 | H37: =F37-G37 -> 0 | I37: =SUMIFS(Del!$C:$C,Del!$B:$B,'Element wise-detail Summary'!$A37) -> 1 | J37: =F37-I37 -> 0 | K37: =G37-I37 -> 0 | L37: =SUMIF(Ere!$B:$B,'Element wise-detail Summary'!$A37,Ere!$C:$C) -> 1 | M37: =F37-L37 -> 0 | N37: =I37*E37 -> 2.923
A38: AZ1-V19-T1C15S-003 | B38: =VLOOKUP(A38,'AFC Data details'!$B:$E,4,0) -> V19 | C38: Zone-1 | D38: BW | E38: =VLOOKUP(A38,'AFC Data details'!$B:$P,15,0) -> 2.923 | F38: =SUMIFS('AFC Data details'!C:C,'AFC Data details'!$B:$B,'Element wise-detail Summary'!$A38) -> 1 | G38: =SUMIFS(Cast!$C:$C,Cast!$B:$B,'Element wise-detail Summary'!$A38) -> 1 | H38: =F38-G38 -> 0 | I38: =SUMIFS(Del!$C:$C,Del!$B:$B,'Element wise-detail Summary'!$A38) -> 1 | J38: =F38-I38 -> 0 | K38: =G38-I38 -> 0 | L38: =SUMIF(Ere!$B:$B,'Element wise-detail Summary'!$A38,Ere!$C:$C) -> 1 | M38: =F38-L38 -> 0 | N38: =I38*E38 -> 2.923
A39: AZ1-V19-T1C17-001 | B39: =VLOOKUP(A39,'AFC Data details'!$B:$E,4,0) -> V19 | C39: Zone-1 | D39: BW | E39: =VLOOKUP(A39,'AFC Data details'!$B:$P,15,0) -> 2.635 | F39: =SUMIFS('AFC Data details'!C:C,'AFC Data details'!$B:$B,'Element wise-detail Summary'!$A39) -> 1 | G39: =SUMIFS(Cast!$C:$C,Cast!$B:$B,'Element wise-detail Summary'!$A39) -> 1 | H39: =F39-G39 -> 0 | I39: =SUMIFS(Del!$C:$C,Del!$B:$B,'Element wise-detail Summary'!$A39) -> 1 | J39: =F39-I39 -> 0 | K39: =G39-I39 -> 0 | L39: =SUMIF(Ere!$B:$B,'Element wise-detail Summary'!$A39,Ere!$C:$C) -> 1 | M39: =F39-L39 -> 0 | N39: =I39*E39 -> 2.635
A40: AZ1-V19-T1C18-001 | B40: =VLOOKUP(A40,'AFC Data details'!$B:$E,4,0) -> V19 | C40: Zone-1 | D40: BW | E40: =VLOOKUP(A40,'AFC Data details'!$B:$P,15,0) -> 2.96 | F40: =SUMIFS('AFC Data details'!C:C,'AFC Data details'!$B:$B,'Element wise-detail Summary'!$A40) -> 1 | G40: =SUMIFS(Cast!$C:$C,Cast!$B:$B,'Element wise-detail Summary'!$A40) -> 1 | H40: =F40-G40 -> 0 | I40: =SUMIFS(Del!$C:$C,Del!$B:$B,'Element wise-detail Summary'!$A40) -> 1 | J40: =F40-I40 -> 0 | K40: =G40-I40 -> 0 | L40: =SUMIF(Ere!$B:$B,'Element wise-detail Summary'!$A40,Ere!$C:$C) -> 1 | M40: =F40-L40 -> 0 | N40: =I40*E40 -> 2.96
A41: AZ1-V19-T1C18-002 | B41: =VLOOKUP(A41,'AFC Data details'!$B:$E,4,0) -> V19 | C41: Zone-1 | D41: BW | E41: =VLOOKUP(A41,'AFC Data details'!$B:$P,15,0) -> 3.032 | F41: =SUMIFS('AFC Data details'!C:C,'AFC Data details'!$B:$B,'Element wise-detail Summary'!$A41) -> 1 | G41: =SUMIFS(Cast!$C:$C,Cast!$B:$B,'Element wise-detail Summary'!$A41) -> 1 | H41: =F41-G41 -> 0 | I41: =SUMIFS(Del!$C:$C,Del!$B:$B,'Element wise-detail Summary'!$A41) -> 1 | J41: =F41-I41 -> 0 | K41: =G41-I41 -> 0 | L41: =SUMIF(Ere!$B:$B,'Element wise-detail Summary'!$A41,Ere!$C:$C) -> 1 | M41: =F41-L41 -> 0 | N41: =I41*E41 -> 3.032
A42: AZ1-V19-T1C18-003 | B42: =VLOOKUP(A42,'AFC Data details'!$B:$E,4,0) -> V19 | C42: Zone-1 | D42: BW | E42: =VLOOKUP(A42,'AFC Data details'!$B:$P,15,0) -> 3.103 | F42: =SUMIFS('AFC Data details'!C:C,'AFC Data details'!$B:$B,'Element wise-detail Summary'!$A42) -> 1 | G42: =SUMIFS(Cast!$C:$C,Cast!$B:$B,'Element wise-detail Summary'!$A42) -> 1 | H42: =F42-G42 -> 0 | I42: =SUMIFS(Del!$C:$C,Del!$B:$B,'Element wise-detail Summary'!$A42) -> 1 | J42: =F42-I42 -> 0 | K42: =G42-I42 -> 0 | L42: =SUMIF(Ere!$B:$B,'Element wise-detail Summary'!$A42,Ere!$C:$C) -> 1 | M42: =F42-L42 -> 0 | N42: =I42*E42 -> 3.103
... A1050: AZ8-PV44-T3C4-001 | B1050: =VLOOKUP(A1050,'AFC Data details'!$B:$E,4,0) -> PV44 | C1050: Zone-8 | D1050: BW | E1050: =VLOOKUP(A1050,'AFC Data details'!$B:$P,15,0) -> 1.421 | F1050: =SUMIFS('AFC Data details'!C:C,'AFC Data details'!$B:$B,'Element wise-detail Summary'!$A1050) -> 1 | G1050: =SUMIFS(Cast!$C:$C,Cast!$B:$B,'Element wise-detail Summary'!$A1050) -> 1 | H1050: =F1050-G1050 -> 0 | I1050: =SUMIFS(Del!$C:$C,Del!$B:$B,'Element wise-detail Summary'!$A1050) -> 0 | J1050: =F1050-I1050 -> 1 | K1050: =G1050-I1050 -> 1 | L1050: =SUMIF(Ere!$B:$B,'Element wise-detail Summary'!$A1050,Ere!$C:$C) -> 0 | M1050: =F1050-L1050 -> 1 | N1050: =I1050*E1050 -> 0
A1051: AZ4-V01-T1C19-001 | B1051: =VLOOKUP(A1051,'AFC Data details'!$B:$E,4,0) -> V01 | C1051: Zone-4 | D1051: BW | E1051: =VLOOKUP(A1051,'AFC Data details'!$B:$P,15,0) -> 4.232 | F1051: =SUMIFS('AFC Data details'!C:C,'AFC Data details'!$B:$B,'Element wise-detail Summary'!$A1051) -> 1 | G1051: =SUMIFS(Cast!$C:$C,Cast!$B:$B,'Element wise-detail Summary'!$A1051) -> 1 | H1051: =F1051-G1051 -> 0 | I1051: =SUMIFS(Del!$C:$C,Del!$B:$B,'Element wise-detail Summary'!$A1051) -> 1 | J1051: =F1051-I1051 -> 0 | K1051: =G1051-I1051 -> 0 | L1051: =SUMIF(Ere!$B:$B,'Element wise-detail Summary'!$A1051,Ere!$C:$C) -> 1 | M1051: =F1051-L1051 -> 0
A1052: AZ4-V01-T1C19-002 | B1052: =VLOOKUP(A1052,'AFC Data details'!$B:$E,4,0) -> V01 | C1052: Zone-4 | D1052: BW | E1052: =VLOOKUP(A1052,'AFC Data details'!$B:$P,15,0) -> 4.286 | F1052: =SUMIFS('AFC Data details'!C:C,'AFC Data details'!$B:$B,'Element wise-detail Summary'!$A1052) -> 1 | G1052: =SUMIFS(Cast!$C:$C,Cast!$B:$B,'Element wise-detail Summary'!$A1052) -> 1 | H1052: =F1052-G1052 -> 0 | I1052: =SUMIFS(Del!$C:$C,Del!$B:$B,'Element wise-detail Summary'!$A1052) -> 1 | J1052: =F1052-I1052 -> 0 | K1052: =G1052-I1052 -> 0 | L1052: =SUMIF(Ere!$B:$B,'Element wise-detail Summary'!$A1052,Ere!$C:$C) -> 1 | M1052: =F1052-L1052 -> 0
A1053: AZ4-V01-T1C19-003 | B1053: =VLOOKUP(A1053,'AFC Data details'!$B:$E,4,0) -> V01 | C1053: Zone-4 | D1053: BW | E1053: =VLOOKUP(A1053,'AFC Data details'!$B:$P,15,0) -> 4.286 | F1053: =SUMIFS('AFC Data details'!C:C,'AFC Data details'!$B:$B,'Element wise-detail Summary'!$A1053) -> 1 | G1053: =SUMIFS(Cast!$C:$C,Cast!$B:$B,'Element wise-detail Summary'!$A1053) -> 1 | H1053: =F1053-G1053 -> 0 | I1053: =SUMIFS(Del!$C:$C,Del!$B:$B,'Element wise-detail Summary'!$A1053) -> 1 | J1053: =F1053-I1053 -> 0 | K1053: =G1053-I1053 -> 0 | L1053: =SUMIF(Ere!$B:$B,'Element wise-detail Summary'!$A1053,Ere!$C:$C) -> 1 | M1053: =F1053-L1053 -> 0
A1054: AZ4-V01-T1C19-004 | B1054: =VLOOKUP(A1054,'AFC Data details'!$B:$E,4,0) -> V01 | C1054: Zone-4 | D1054: BW | E1054: =VLOOKUP(A1054,'AFC Data details'!$B:$P,15,0) -> 4.286 | F1054: =SUMIFS('AFC Data details'!C:C,'AFC Data details'!$B:$B,'Element wise-detail Summary'!$A1054) -> 1 | G1054: =SUMIFS(Cast!$C:$C,Cast!$B:$B,'Element wise-detail Summary'!$A1054) -> 1 | H1054: =F1054-G1054 -> 0 | I1054: =SUMIFS(Del!$C:$C,Del!$B:$B,'Element wise-detail Summary'!$A1054) -> 1 | J1054: =F1054-I1054 -> 0 | K1054: =G1054-I1054 -> 0 | L1054: =SUMIF(Ere!$B:$B,'Element wise-detail Summary'!$A1054,Ere!$C:$C) -> 1 | M1054: =F1054-L1054 -> 0
A1055: AZ4-V01-T1C19-005 | B1055: =VLOOKUP(A1055,'AFC Data details'!$B:$E,4,0) -> V01 | C1055: Zone-4 | D1055: BW | E1055: =VLOOKUP(A1055,'AFC Data details'!$B:$P,15,0) -> 4.286 | F1055: =SUMIFS('AFC Data details'!C:C,'AFC Data details'!$B:$B,'Element wise-detail Summary'!$A1055) -> 1 | G1055: =SUMIFS(Cast!$C:$C,Cast!$B:$B,'Element wise-detail Summary'!$A1055) -> 1 | H1055: =F1055-G1055 -> 0 | I1055: =SUMIFS(Del!$C:$C,Del!$B:$B,'Element wise-detail Summary'!$A1055) -> 1 | J1055: =F1055-I1055 -> 0 | K1055: =G1055-I1055 -> 0 | L1055: =SUMIF(Ere!$B:$B,'Element wise-detail Summary'!$A1055,Ere!$C:$C) -> 1 | M1055: =F1055-L1055 -> 0
A1056: AZ4-V01-T1C19-006 | B1056: =VLOOKUP(A1056,'AFC Data details'!$B:$E,4,0) -> V01 | C1056: Zone-4 | D1056: BW | E1056: =VLOOKUP(A1056,'AFC Data details'!$B:$P,15,0) -> 3.822 | F1056: =SUMIFS('AFC Data details'!C:C,'AFC Data details'!$B:$B,'Element wise-detail Summary'!$A1056) -> 1 | G1056: =SUMIFS(Cast!$C:$C,Cast!$B:$B,'Element wise-detail Summary'!$A1056) -> 1 | H1056: =F1056-G1056 -> 0 | I1056: =SUMIFS(Del!$C:$C,Del!$B:$B,'Element wise-detail Summary'!$A1056) -> 1 | J1056: =F1056-I1056 -> 0 | K1056: =G1056-I1056 -> 0 | L1056: =SUMIF(Ere!$B:$B,'Element wise-detail Summary'!$A1056,Ere!$C:$C) -> 1 | M1056: =F1056-L1056 -> 0
A1057: AZ4-V01-T1C19-007 | B1057: =VLOOKUP(A1057,'AFC Data details'!$B:$E,4,0) -> V01 | C1057: Zone-4 | D1057: BW | E1057: =VLOOKUP(A1057,'AFC Data details'!$B:$P,15,0) -> 2.672 | F1057: =SUMIFS('AFC Data details'!C:C,'AFC Data details'!$B:$B,'Element wise-detail Summary'!$A1057) -> 1 | G1057: =SUMIFS(Cast!$C:$C,Cast!$B:$B,'Element wise-detail Summary'!$A1057) -> 1 | H1057: =F1057-G1057 -> 0 | I1057: =SUMIFS(Del!$C:$C,Del!$B:$B,'Element wise-detail Summary'!$A1057) -> 1 | J1057: =F1057-I1057 -> 0 | K1057: =G1057-I1057 -> 0 | L1057: =SUMIF(Ere!$B:$B,'Element wise-detail Summary'!$A1057,Ere!$C:$C) -> 1 | M1057: =F1057-L1057 -> 0
A1058: AZ4-V02-T1C19-001 | B1058: V02 | C1058: Zone-4 | D1058: BW | E1058: =VLOOKUP(A1058,'AFC Data details'!$B:$P,15,0) -> 1.95 | F1058: =SUMIFS('AFC Data details'!C:C,'AFC Data details'!$B:$B,'Element wise-detail Summary'!$A1058) -> 1 | G1058: =SUMIFS(Cast!$C:$C,Cast!$B:$B,'Element wise-detail Summary'!$A1058) -> 1 | H1058: =F1058-G1058 -> 0 | I1058: =SUMIFS(Del!$C:$C,Del!$B:$B,'Element wise-detail Summary'!$A1058) -> 1 | J1058: =F1058-I1058 -> 0 | K1058: =G1058-I1058 -> 0 | L1058: =SUMIF(Ere!$B:$B,'Element wise-detail Summary'!$A1058,Ere!$C:$C) -> 1 | M1058: =F1058-L1058 -> 0
...

Sheet Cast
A1: Date | B1: Element ID | C1: Qty | D1: Villa No. | E1: Zone | F1: Element Check | G1: Remarks | H1: VOL | I1: =SUBTOTAL(9,C:C) -> 1110 | L1: =MAXA(A:A) -> 46148
A2: 45897 | B2: AMR-V18-T1C16-001 | C2: 1 | D2: =VLOOKUP(B2,'Element wise-detail Summary'!$A:$D,2,0) -> V18 | E2: =IFERROR(VLOOKUP(B2,'Element wise-detail Summary'!$A:$D,3,0),0) -> MOCKUP | F2: =VLOOKUP(B2,'AFC Data details'!$B:$B,1,0) -> AMR-V18-T1C16-001 | H2: =_xlfn.XLOOKUP(B2,'AFC Data details'!B:B,'AFC Data details'!P:P) -> 2.138
A3: 45897 | B3: AMR-V17-T1C10-001 | C3: 1 | D3: =VLOOKUP(B3,'Element wise-detail Summary'!$A:$D,2,0) -> V17 | E3: =IFERROR(VLOOKUP(B3,'Element wise-detail Summary'!$A:$D,3,0),0) -> MOCKUP | F3: =VLOOKUP(B3,'AFC Data details'!$B:$B,1,0) -> AMR-V17-T1C10-001 | H3: =_xlfn.XLOOKUP(B3,'AFC Data details'!B:B,'AFC Data details'!P:P) -> 1.787
A4: 45897 | B4: AMR-V18-T1C10-002 | C4: 1 | D4: =VLOOKUP(B4,'Element wise-detail Summary'!$A:$D,2,0) -> V18 | E4: =IFERROR(VLOOKUP(B4,'Element wise-detail Summary'!$A:$D,3,0),0) -> MOCKUP | F4: =VLOOKUP(B4,'AFC Data details'!$B:$B,1,0) -> AMR-V18-T1C10-002 | H4: =_xlfn.XLOOKUP(B4,'AFC Data details'!B:B,'AFC Data details'!P:P) -> 1.617
A5: 45897 | B5: AMR-V17-T1C11-003 | C5: 1 | D5: =VLOOKUP(B5,'Element wise-detail Summary'!$A:$D,2,0) -> V17 | E5: =IFERROR(VLOOKUP(B5,'Element wise-detail Summary'!$A:$D,3,0),0) -> MOCKUP | F5: =VLOOKUP(B5,'AFC Data details'!$B:$B,1,0) -> AMR-V17-T1C11-003 | H5: =_xlfn.XLOOKUP(B5,'AFC Data details'!B:B,'AFC Data details'!P:P) -> 1.977
A6: 45899 | B6: AMR-V18-T3C3-001 | C6: 1 | D6: =VLOOKUP(B6,'Element wise-detail Summary'!$A:$D,2,0) -> V18 | E6: =IFERROR(VLOOKUP(B6,'Element wise-detail Summary'!$A:$D,3,0),0) -> MOCKUP | F6: =VLOOKUP(B6,'AFC Data details'!$B:$B,1,0) -> AMR-V18-T3C3-001 | H6: =_xlfn.XLOOKUP(B6,'AFC Data details'!B:B,'AFC Data details'!P:P) -> 1.462
A7: 45899 | B7: AMR-V18-T3C3-002 | C7: 1 | D7: =VLOOKUP(B7,'Element wise-detail Summary'!$A:$D,2,0) -> V18 | E7: =IFERROR(VLOOKUP(B7,'Element wise-detail Summary'!$A:$D,3,0),0) -> MOCKUP | F7: =VLOOKUP(B7,'AFC Data details'!$B:$B,1,0) -> AMR-V18-T3C3-002 | H7: =_xlfn.XLOOKUP(B7,'AFC Data details'!B:B,'AFC Data details'!P:P) -> 1.462
A8: 45899 | B8: AMR-V18-T3C3-003 | C8: 1 | D8: =VLOOKUP(B8,'Element wise-detail Summary'!$A:$D,2,0) -> V18 | E8: =IFERROR(VLOOKUP(B8,'Element wise-detail Summary'!$A:$D,3,0),0) -> MOCKUP | F8: =VLOOKUP(B8,'AFC Data details'!$B:$B,1,0) -> AMR-V18-T3C3-003 | H8: =_xlfn.XLOOKUP(B8,'AFC Data details'!B:B,'AFC Data details'!P:P) -> 1.462
A9: 45904 | B9: AMR-V18-T1C3-001 | C9: 1 | D9: =VLOOKUP(B9,'Element wise-detail Summary'!$A:$D,2,0) -> V18 | E9: =IFERROR(VLOOKUP(B9,'Element wise-detail Summary'!$A:$D,3,0),0) -> MOCKUP | F9: =VLOOKUP(B9,'AFC Data details'!$B:$B,1,0) -> AMR-V18-T1C3-001 | H9: =_xlfn.XLOOKUP(B9,'AFC Data details'!B:B,'AFC Data details'!P:P) -> 1.251
A10: 45904 | B10: AMR-V17-T2C1-001 | C10: 1 | D10: =VLOOKUP(B10,'Element wise-detail Summary'!$A:$D,2,0) -> V17 | E10: =IFERROR(VLOOKUP(B10,'Element wise-detail Summary'!$A:$D,3,0),0) -> MOCKUP | F10: =VLOOKUP(B10,'AFC Data details'!$B:$B,1,0) -> AMR-V17-T2C1-001 | H10: =_xlfn.XLOOKUP(B10,'AFC Data details'!B:B,'AFC Data details'!P:P) -> 1.413
A11: 45910 | B11: AMR-V17-T3C6-002 | C11: 1 | D11: =VLOOKUP(B11,'Element wise-detail Summary'!$A:$D,2,0) -> V17 | E11: =IFERROR(VLOOKUP(B11,'Element wise-detail Summary'!$A:$D,3,0),0) -> MOCKUP | F11: =VLOOKUP(B11,'AFC Data details'!$B:$B,1,0) -> AMR-V17-T3C6-002 | H11: =_xlfn.XLOOKUP(B11,'AFC Data details'!B:B,'AFC Data details'!P:P) -> 1.69
A12: 45911 | B12: AMR-V17-T1C10-002 | C12: 1 | D12: =VLOOKUP(B12,'Element wise-detail Summary'!$A:$D,2,0) -> V17 | E12: =IFERROR(VLOOKUP(B12,'Element wise-detail Summary'!$A:$D,3,0),0) -> MOCKUP | F12: =VLOOKUP(B12,'AFC Data details'!$B:$B,1,0) -> AMR-V17-T1C10-002 | H12: =_xlfn.XLOOKUP(B12,'AFC Data details'!B:B,'AFC Data details'!P:P) -> 1.779
A13: 45911 | B13: AMR-V17-T3C6-001 | C13: 1 | D13: =VLOOKUP(B13,'Element wise-detail Summary'!$A:$D,2,0) -> V17 | E13: =IFERROR(VLOOKUP(B13,'Element wise-detail Summary'!$A:$D,3,0),0) -> MOCKUP | F13: =VLOOKUP(B13,'AFC Data details'!$B:$B,1,0) -> AMR-V17-T3C6-001 | H13: =_xlfn.XLOOKUP(B13,'AFC Data details'!B:B,'AFC Data details'!P:P) -> 1.69
... A1065: 46105 | B1065: AZ7-PV02-T3C6-002 | C1065: 1 | D1065: =VLOOKUP(B1065,'Element wise-detail Summary'!$A:$D,2,0) -> PV02 | E1065: =IFERROR(VLOOKUP(B1065,'Element wise-detail Summary'!$A:$D,3,0),0) -> Zone-7 | F1065: =VLOOKUP(B1065,'AFC Data details'!$B:$B,1,0) -> AZ7-PV02-T3C6-002 | H1065: =_xlfn.XLOOKUP(B1065,'AFC Data details'!B:B,'AFC Data details'!P:P) -> 1.242
A1066: 46105 | B1066: AZ1-V20-T1C6-001 | C1066: 0 | D1066: =VLOOKUP(B1066,'Element wise-detail Summary'!$A:$D,2,0) -> V20 | E1066: =IFERROR(VLOOKUP(B1066,'Element wise-detail Summary'!$A:$D,3,0),0) -> Zone-1 | F1066: =VLOOKUP(B1066,'AFC Data details'!$B:$B,1,0) -> AZ1-V20-T1C6-001 | H1066: =_xlfn.XLOOKUP(B1066,'AFC Data details'!B:B,'AFC Data details'!P:P) -> 2.097 | I1066: RECAST
A1067: 46106 | B1067: AZ6-PV34-T3C4-001 | C1067: 1 | D1067: =VLOOKUP(B1067,'Element wise-detail Summary'!$A:$D,2,0) -> PV34 | E1067: =IFERROR(VLOOKUP(B1067,'Element wise-detail Summary'!$A:$D,3,0),0) -> Zone-6 | F1067: =VLOOKUP(B1067,'AFC Data details'!$B:$B,1,0) -> AZ6-PV34-T3C4-001 | H1067: =_xlfn.XLOOKUP(B1067,'AFC Data details'!B:B,'AFC Data details'!P:P) -> 1.291
A1068: 46106 | B1068: AZ7-PV14-T3C4-002 | C1068: 1 | D1068: =VLOOKUP(B1068,'Element wise-detail Summary'!$A:$D,2,0) -> PV14 | E1068: =IFERROR(VLOOKUP(B1068,'Element wise-detail Summary'!$A:$D,3,0),0) -> Zone-7 | F1068: =VLOOKUP(B1068,'AFC Data details'!$B:$B,1,0) -> AZ7-PV14-T3C4-002 | H1068: =_xlfn.XLOOKUP(B1068,'AFC Data details'!B:B,'AFC Data details'!P:P) -> 1.411
A1069: 46107 | B1069: AZ6-PV35-T3C4-001 | C1069: 1 | D1069: =VLOOKUP(B1069,'Element wise-detail Summary'!$A:$D,2,0) -> PV35 | E1069: =IFERROR(VLOOKUP(B1069,'Element wise-detail Summary'!$A:$D,3,0),0) -> Zone-6 | F1069: =VLOOKUP(B1069,'AFC Data details'!$B:$B,1,0) -> AZ6-PV35-T3C4-001 | H1069: =_xlfn.XLOOKUP(B1069,'AFC Data details'!B:B,'AFC Data details'!P:P) -> 1.395
A1070: 46107 | B1070: AZ7-PV12-T3C4-002 | C1070: 1 | D1070: =VLOOKUP(B1070,'Element wise-detail Summary'!$A:$D,2,0) -> PV12 | E1070: =IFERROR(VLOOKUP(B1070,'Element wise-detail Summary'!$A:$D,3,0),0) -> Zone-7 | F1070: =VLOOKUP(B1070,'AFC Data details'!$B:$B,1,0) -> AZ7-PV12-T3C4-002 | H1070: =_xlfn.XLOOKUP(B1070,'AFC Data details'!B:B,'AFC Data details'!P:P) -> 1.371
A1071: 46109 | B1071: AZ6-PV35-T3C4-002 | C1071: 1 | D1071: =VLOOKUP(B1071,'Element wise-detail Summary'!$A:$D,2,0) -> PV35 | E1071: =IFERROR(VLOOKUP(B1071,'Element wise-detail Summary'!$A:$D,3,0),0) -> Zone-6 | F1071: =VLOOKUP(B1071,'AFC Data details'!$B:$B,1,0) -> AZ6-PV35-T3C4-002 | H1071: =_xlfn.XLOOKUP(B1071,'AFC Data details'!B:B,'AFC Data details'!P:P) -> 1.285
A1072: 46109 | B1072: AZ6-PV33-T3C4-001 | C1072: 0 | D1072: =VLOOKUP(B1072,'Element wise-detail Summary'!$A:$D,2,0) -> PV33 | E1072: =IFERROR(VLOOKUP(B1072,'Element wise-detail Summary'!$A:$D,3,0),0) -> Zone-6 | F1072: =VLOOKUP(B1072,'AFC Data details'!$B:$B,1,0) -> AZ6-PV33-T3C4-001 | H1072: =_xlfn.XLOOKUP(B1072,'AFC Data details'!B:B,'AFC Data details'!P:P) -> 1.378
A1073: 46110 | B1073: AZ7-PV13-T3C4-001 | C1073: 1 | D1073: =VLOOKUP(B1073,'Element wise-detail Summary'!$A:$D,2,0) -> PV13 | E1073: =IFERROR(VLOOKUP(B1073,'Element wise-detail Summary'!$A:$D,3,0),0) -> Zone-7 | F1073: =VLOOKUP(B1073,'AFC Data details'!$B:$B,1,0) -> AZ7-PV13-T3C4-001 | H1073: =_xlfn.XLOOKUP(B1073,'AFC Data details'!B:B,'AFC Data details'!P:P) -> 1.399
A1074: 46111 | B1074: AZ6-PV27-T3C4-001 | C1074: 1 | D1074: =VLOOKUP(B1074,'Element wise-detail Summary'!$A:$D,2,0) -> PV27 | E1074: =IFERROR(VLOOKUP(B1074,'Element wise-detail Summary'!$A:$D,3,0),0) -> Zone-6 | F1074: =VLOOKUP(B1074,'AFC Data details'!$B:$B,1,0) -> AZ6-PV27-T3C4-001 | H1074: =_xlfn.XLOOKUP(B1074,'AFC Data details'!B:B,'AFC Data details'!P:P) -> 1.296
A1075: 46111 | B1075: AZ7-PV15-T3C4-001 | C1075: 1 | D1075: =VLOOKUP(B1075,'Element wise-detail Summary'!$A:$D,2,0) -> PV15 | E1075: =IFERROR(VLOOKUP(B1075,'Element wise-detail Summary'!$A:$D,3,0),0) -> Zone-7 | F1075: =VLOOKUP(B1075,'AFC Data details'!$B:$B,1,0) -> AZ7-PV15-T3C4-001 | H1075: =_xlfn.XLOOKUP(B1075,'AFC Data details'!B:B,'AFC Data details'!P:P) -> 1.382
A1076: 46112 | B1076: AZ6-PV33-T3C4-002 | C1076: 1 | D1076: =VLOOKUP(B1076,'Element wise-detail Summary'!$A:$D,2,0) -> PV33 | E1076: =IFERROR(VLOOKUP(B1076,'Element wise-detail Summary'!$A:$D,3,0),0) -> Zone-6 | F1076: =VLOOKUP(B1076,'AFC Data details'!$B:$B,1,0) -> AZ6-PV33-T3C4-002 | H1076: =_xlfn.XLOOKUP(B1076,'AFC Data details'!B:B,'AFC Data details'!P:P) -> 1.265
A1077: 46113 | B1077: AZ6-PV18-T3C4-001 | C1077: 1 | D1077: =VLOOKUP(B1077,'Element wise-detail Summary'!$A:$D,2,0) -> PV18 | E1077: =IFERROR(VLOOKUP(B1077,'Element wise-detail Summary'!$A:$D,3,0),0) -> Zone-6 | F1077: =VLOOKUP(B1077,'AFC Data details'!$B:$B,1,0) -> AZ6-PV18-T3C4-001 | H1077: =_xlfn.XLOOKUP(B1077,'AFC Data details'!B:B,'AFC Data details'!P:P) -> 1.214
A1078: 46113 | B1078: AZ7-PV16-T3C4-002 | C1078: 1 | D1078: =VLOOKUP(B1078,'Element wise-detail Summary'!$A:$D,2,0) -> PV16 | E1078: =IFERROR(VLOOKUP(B1078,'Element wise-detail Summary'!$A:$D,3,0),0) -> Zone-7 | F1078: =VLOOKUP(B1078,'AFC Data details'!$B:$B,1,0) -> AZ7-PV16-T3C4-002 | H1078: =_xlfn.XLOOKUP(B1078,'AFC Data details'!B:B,'AFC Data details'!P:P) -> 1.332
... A1113: 46132 | B1113: AZ8-PV45-T1C3-001 | C1113: 1 | D1113: =VLOOKUP(B1113,'Element wise-detail Summary'!$A:$D,2,0) -> PV45 | E1113: =IFERROR(VLOOKUP(B1113,'Element wise-detail Summary'!$A:$D,3,0),0) -> Zone-8 | F1113: =VLOOKUP(B1113,'AFC Data details'!$B:$B,1,0) -> AZ8-PV45-T1C3-001 | H1113: =_xlfn.XLOOKUP(B1113,'AFC Data details'!B:B,'AFC Data details'!P:P) -> 1.318
A1114: 46146 | B1114: AZ6-PV33-T1C6-003 | C1114: 1 | D1114: =VLOOKUP(B1114,'Element wise-detail Summary'!$A:$D,2,0) -> PV33 | E1114: =IFERROR(VLOOKUP(B1114,'Element wise-detail Summary'!$A:$D,3,0),0) -> Zone-6 | F1114: =VLOOKUP(B1114,'AFC Data details'!$B:$B,1,0) -> AZ6-PV33-T1C6-003 | H1114: =_xlfn.XLOOKUP(B1114,'AFC Data details'!B:B,'AFC Data details'!P:P) -> 2.084 | I1114: RECAST NCR#168
A1115: 46148 | B1115: AZ6-PV33-T3C4-001 | C1115: 1 | D1115: =VLOOKUP(B1115,'Element wise-detail Summary'!$A:$D,2,0) -> PV33 | E1115: =IFERROR(VLOOKUP(B1115,'Element wise-detail Summary'!$A:$D,3,0),0) -> Zone-6 | F1115: =VLOOKUP(B1115,'AFC Data details'!$B:$B,1,0) -> AZ6-PV33-T3C4-001 | H1115: =_xlfn.XLOOKUP(B1115,'AFC Data details'!B:B,'AFC Data details'!P:P) -> 1.378 | I1115: RECAST NCR#170

Sheet Del
A1: Date | B1: Element ID | C1: Del.Qty | D1: Del. Note No. | E1: Zone | F1: Element Check | G1: =SUBTOTAL(9,C:C) -> 635 | I1: =MAXA(A:A) -> 46241
A2: 45923 | B2: AMR-V17-T3C6-002 | C2: 1 | D2: SPBM-02070 | E2: =VLOOKUP(B2,'Element wise-detail Summary'!$A:$C,3,0) -> MOCKUP | F2: =VLOOKUP(B2,'AFC Data details'!$B:$B,1,0) -> AMR-V17-T3C6-002
A3: 45923 | B3: AMR-V17-T1C11-001 | C3: 1 | D3: SPBM-02070 | E3: =VLOOKUP(B3,'Element wise-detail Summary'!$A:$C,3,0) -> MOCKUP | F3: =VLOOKUP(B3,'AFC Data details'!$B:$B,1,0) -> AMR-V17-T1C11-001
A4: 45923 | B4: AZ1-V19-T1C15S-002 | C4: 1 | D4: SPBM-02070 | E4: =VLOOKUP(B4,'Element wise-detail Summary'!$A:$C,3,0) -> Zone-1 | F4: =VLOOKUP(B4,'AFC Data details'!$B:$B,1,0) -> AZ1-V19-T1C15S-002
A5: 45923 | B5: AMR-V17-T3C6-003 | C5: 1 | D5: SPBM-02070 | E5: =VLOOKUP(B5,'Element wise-detail Summary'!$A:$C,3,0) -> MOCKUP | F5: =VLOOKUP(B5,'AFC Data details'!$B:$B,1,0) -> AMR-V17-T3C6-003
A6: 45923 | B6: AZ1-V19-T2C1-001 | C6: 1 | D6: SPBM-02071 | E6: =VLOOKUP(B6,'Element wise-detail Summary'!$A:$C,3,0) -> Zone-1 | F6: =VLOOKUP(B6,'AFC Data details'!$B:$B,1,0) -> AZ1-V19-T2C1-001
A7: 45923 | B7: AMR-V17-T1C10-003 | C7: 1 | D7: SPBM-02071 | E7: =VLOOKUP(B7,'Element wise-detail Summary'!$A:$C,3,0) -> MOCKUP | F7: =VLOOKUP(B7,'AFC Data details'!$B:$B,1,0) -> AMR-V17-T1C10-003
A8: 45923 | B8: AMR-V18-T1C10-007 | C8: 1 | D8: SPBM-02071 | E8: =VLOOKUP(B8,'Element wise-detail Summary'!$A:$C,3,0) -> MOCKUP | F8: =VLOOKUP(B8,'AFC Data details'!$B:$B,1,0) -> AMR-V18-T1C10-007
A9: 45923 | B9: AMR-V18-T1C10-003 | C9: 1 | D9: SPBM-02071 | E9: =VLOOKUP(B9,'Element wise-detail Summary'!$A:$C,3,0) -> MOCKUP | F9: =VLOOKUP(B9,'AFC Data details'!$B:$B,1,0) -> AMR-V18-T1C10-003
A10: 45929 | B10: AMR-V17-T1C10-002 | C10: 1 | D10: SPBM-02172 | E10: =VLOOKUP(B10,'Element wise-detail Summary'!$A:$C,3,0) -> MOCKUP | F10: =VLOOKUP(B10,'AFC Data details'!$B:$B,1,0) -> AMR-V17-T1C10-002
A11: 45929 | B11: AMR-V18-T1C3-001 | C11: 1 | D11: SPBM-02172 | E11: =VLOOKUP(B11,'Element wise-detail Summary'!$A:$C,3,0) -> MOCKUP | F11: =VLOOKUP(B11,'AFC Data details'!$B:$B,1,0) -> AMR-V18-T1C3-001
A12: 45929 | B12: AMR-V18-T3C3-003 | C12: 1 | D12: SPBM-02172 | E12: =VLOOKUP(B12,'Element wise-detail Summary'!$A:$C,3,0) -> MOCKUP | F12: =VLOOKUP(B12,'AFC Data details'!$B:$B,1,0) -> AMR-V18-T3C3-003
A13: 45929 | B13: AMR-V18-T3C3-001 | C13: 1 | D13: SPBM-02172 | E13: =VLOOKUP(B13,'Element wise-detail Summary'!$A:$C,3,0) -> MOCKUP | F13: =VLOOKUP(B13,'AFC Data details'!$B:$B,1,0) -> AMR-V18-T3C3-001
... A28: 45936 | B28: AMR-V18-T1C10-002 | C28: 1 | D28: SPBM-02340 | E28: =VLOOKUP(B28,'Element wise-detail Summary'!$A:$C,3,0) -> MOCKUP | F28: =VLOOKUP(B28,'AFC Data details'!$B:$B,1,0) -> AMR-V18-T1C10-002
A29: 45936 | B29: AMR-V17-T1C12-001 | C29: 1 | E29: =VLOOKUP(B29,'Element wise-detail Summary'!$A:$C,3,0) -> MOCKUP | F29: =VLOOKUP(B29,'AFC Data details'!$B:$B,1,0) -> AMR-V17-T1C12-001
A30: 45936 | B30: AMR-V18-T1C16-001 | C30: 1 | E30: =VLOOKUP(B30,'Element wise-detail Summary'!$A:$C,3,0) -> MOCKUP | F30: =VLOOKUP(B30,'AFC Data details'!$B:$B,1,0) -> AMR-V18-T1C16-001
A31: 45936 | B31: AMR-V18-T3C6-001 | C31: 1 | E31: =VLOOKUP(B31,'Element wise-detail Summary'!$A:$C,3,0) -> MOCKUP | F31: =VLOOKUP(B31,'AFC Data details'!$B:$B,1,0) -> AMR-V18-T3C6-001
A32: 45946 | B32: AZ1-V21-T3C4-001 | C32: 1 | D32: SPBM-02564 | E32: =VLOOKUP(B32,'Element wise-detail Summary'!$A:$C,3,0) -> Zone-1 | F32: =VLOOKUP(B32,'AFC Data details'!$B:$B,1,0) -> AZ1-V21-T3C4-001
A33: 45946 | B33: AZ1-V21-T3C4-002 | C33: 1 | D33: SPBM-02564 | E33: =VLOOKUP(B33,'Element wise-detail Summary'!$A:$C,3,0) -> Zone-1 | F33: =VLOOKUP(B33,'AFC Data details'!$B:$B,1,0) -> AZ1-V21-T3C4-002
A34: 45946 | B34: AZ1-V21-T1C6-005 | C34: 1 | D34: SPBM-02564 | E34: =VLOOKUP(B34,'Element wise-detail Summary'!$A:$C,3,0) -> Zone-1 | F34: =VLOOKUP(B34,'AFC Data details'!$B:$B,1,0) -> AZ1-V21-T1C6-005
A35: 45946 | B35: AZ1-V21-T1C6-006 | C35: 1 | D35: SPBM-02564 | E35: =VLOOKUP(B35,'Element wise-detail Summary'!$A:$C,3,0) -> Zone-1 | F35: =VLOOKUP(B35,'AFC Data details'!$B:$B,1,0) -> AZ1-V21-T1C6-006
A36: 45955 | B36: AZ1-V22-T3C4-001 | C36: 1 | D36: SPBM-02777 | E36: =VLOOKUP(B36,'Element wise-detail Summary'!$A:$C,3,0) -> Zone-1 | F36: =VLOOKUP(B36,'AFC Data details'!$B:$B,1,0) -> AZ1-V22-T3C4-001
A37: 45955 | B37: AZ1-V22-T1C6-005 | C37: 1 | D37: SPBM-02777 | E37: =VLOOKUP(B37,'Element wise-detail Summary'!$A:$C,3,0) -> Zone-1 | F37: =VLOOKUP(B37,'AFC Data details'!$B:$B,1,0) -> AZ1-V22-T1C6-005
A38: 45955 | B38: AZ1-V23-T1C6-005 | C38: 1 | D38: SPBM-02777 | E38: =VLOOKUP(B38,'Element wise-detail Summary'!$A:$C,3,0) -> Zone-1 | F38: =VLOOKUP(B38,'AFC Data details'!$B:$B,1,0) -> AZ1-V23-T1C6-005
A39: 45955 | B39: AZ1-V23-T1C6-006 | C39: 1 | D39: SPBM-02777 | E39: =VLOOKUP(B39,'Element wise-detail Summary'!$A:$C,3,0) -> Zone-1 | F39: =VLOOKUP(B39,'AFC Data details'!$B:$B,1,0) -> AZ1-V23-T1C6-006
A40: 45955 | B40: AZ1-V23-T3C4-002 | C40: 1 | D40: SPBM-02779 | E40: =VLOOKUP(B40,'Element wise-detail Summary'!$A:$C,3,0) -> Zone-1 | F40: =VLOOKUP(B40,'AFC Data details'!$B:$B,1,0) -> AZ1-V23-T3C4-002
A41: 45955 | B41: AZ1-V23-T3C4-001 | C41: 1 | D41: SPBM-02779 | E41: =VLOOKUP(B41,'Element wise-detail Summary'!$A:$C,3,0) -> Zone-1 | F41: =VLOOKUP(B41,'AFC Data details'!$B:$B,1,0) -> AZ1-V23-T3C4-001
A42: 45955 | B42: AZ1-V24-T1C1-001 | C42: 1 | D42: SPBM-02779 | E42: =VLOOKUP(B42,'Element wise-detail Summary'!$A:$C,3,0) -> Zone-1 | F42: =VLOOKUP(B42,'AFC Data details'!$B:$B,1,0) -> AZ1-V24-T1C1-001
A43: 45955 | B43: AZ1-V24-T3C4-002 | C43: 1 | D43: SPBM-02779 | E43: =VLOOKUP(B43,'Element wise-detail Summary'!$A:$C,3,0) -> Zone-1 | F43: =VLOOKUP(B43,'AFC Data details'!$B:$B,1,0) -> AZ1-V24-T3C4-002
... A49: 45957 | B49: AZ1-V26-T1C6-006 | C49: 1 | D49: SPBM-02825 | E49: =VLOOKUP(B49,'Element wise-detail Summary'!$A:$C,3,0) -> Zone-1 | F49: =VLOOKUP(B49,'AFC Data details'!$B:$B,1,0) -> AZ1-V26-T1C6-006
B50: AZ1-V34-T1C2-001 | C50: 1 | E50: =VLOOKUP(B50,'Element wise-detail Summary'!$A:$C,3,0) -> Zone-1 | F50: =VLOOKUP(B50,'AFC Data details'!$B:$B,1,0) -> AZ1-V34-T1C2-001
B51: AZ1-V25-T2C1-001 | C51: 1 | E51: =VLOOKUP(B51,'Element wise-detail Summary'!$A:$C,3,0) -> Zone-1 | F51: =VLOOKUP(B51,'AFC Data details'!$B:$B,1,0) -> AZ1-V25-T2C1-001
B52: AZ1-V21-T1C1-001 | C52: 1 | E52: =VLOOKUP(B52,'Element wise-detail Summary'!$A:$C,3,0) -> Zone-1 | F52: =VLOOKUP(B52,'AFC Data details'!$B:$B,1,0) -> AZ1-V21-T1C1-001
B53: AZ1-V21-T2C1-001 | C53: 1 | E53: =VLOOKUP(B53,'Element wise-detail Summary'!$A:$C,3,0) -> Zone-1 | F53: =VLOOKUP(B53,'AFC Data details'!$B:$B,1,0) -> AZ1-V21-T2C1-001
B54: AZ1-V22-T1C6-006 | C54: 1 | E54: =VLOOKUP(B54,'Element wise-detail Summary'!$A:$C,3,0) -> Zone-1 | F54: =VLOOKUP(B54,'AFC Data details'!$B:$B,1,0) -> AZ1-V22-T1C6-006
B55: AZ1-V22-T3C4-002 | C55: 1 | E55: =VLOOKUP(B55,'Element wise-detail Summary'!$A:$C,3,0) -> Zone-1 | F55: =VLOOKUP(B55,'AFC Data details'!$B:$B,1,0) -> AZ1-V22-T3C4-002
B56: AZ1-V23-T2C1-001 | C56: 1 | E56: =VLOOKUP(B56,'Element wise-detail Summary'!$A:$C,3,0) -> Zone-1 | F56: =VLOOKUP(B56,'AFC Data details'!$B:$B,1,0) -> AZ1-V23-T2C1-001
B57: AZ1-V27-T2C1-001 | C57: 1 | E57: =VLOOKUP(B57,'Element wise-detail Summary'!$A:$C,3,0) -> Zone-1 | F57: =VLOOKUP(B57,'AFC Data details'!$B:$B,1,0) -> AZ1-V27-T2C1-001
B58: AZ1-V33-T2C1-001 | C58: 1 | E58: =VLOOKUP(B58,'Element wise-detail Summary'!$A:$C,3,0) -> Zone-1 | F58: =VLOOKUP(B58,'AFC Data details'!$B:$B,1,0) -> AZ1-V33-T2C1-001
B59: AZ1-V24-T1C6-005 | C59: 1 | E59: =VLOOKUP(B59,'Element wise-detail Summary'!$A:$C,3,0) -> Zone-1 | F59: =VLOOKUP(B59,'AFC Data details'!$B:$B,1,0) -> AZ1-V24-T1C6-005
...

Sheet Ere
A1: Date | B1: Element ID | C1: Ins.Qty | D1: Villa No | E1: Zone | F1: Element Check | G1: =SUBTOTAL(9,C:C) -> 581
A2: 45927 | B2: AMR-V17-T1C10-003 | C2: 1 | D2: =VLOOKUP(B2,'Element wise-detail Summary'!$A:$D,2,0) -> V17 | E2: =VLOOKUP(B2,'Element wise-detail Summary'!$A:$D,3,0) -> MOCKUP | F2: =VLOOKUP(B2,'AFC Data details'!$B:$B,1,0) -> AMR-V17-T1C10-003
A3: 45927 | B3: AMR-V17-T1C11-001 | C3: 1 | D3: =VLOOKUP(B3,'Element wise-detail Summary'!$A:$D,2,0) -> V17 | E3: =VLOOKUP(B3,'Element wise-detail Summary'!$A:$D,3,0) -> MOCKUP | F3: =VLOOKUP(B3,'AFC Data details'!$B:$B,1,0) -> AMR-V17-T1C11-001
